Workbook

Sheet Assumptions & Sources
A1: CV Low-Voltage Voltage-Drop Tool | Assumptions & Sources
A3: Parameter | B3: Value
A4: Copper temperature coefficient, α (1/°C) | B4: 0.00393
A5: Default conductor operating temperature (°C) | B5: 90
A6: Default voltage-drop limit | B6: 0.03
A7: Default reactance, X (Ω/km) | B7: 0.08
A8: Reference temperature for Rdc (°C) | B8: 20
A10: Source / method | B10: Reference | C10: How used | D10: Important limitation
A11: Project source | B11: สาย CV ที่ใช้ในโครงการ.xlsx | C11: Selects the project CV cable types included in this tool. | D11: The source contains cable descriptions only; it does not include electrical impedance data.
A12: Manufacturer construction | B12: https://www.pdcable.com/en/product-en/building-and-construction/cv-1-2/ | C12: Confirms Phelps Dodge CV is 0.6/1 kV Cu/XLPE/PVC, IEC 60502-1, 1C/2C/3C/4C/5C. | D12: Verify final catalogue/test values for the exact part number and installation arrangement.
A13: Conductor Rdc | B13: IEC 60228 Class 2 maximum DC resistance at 20°C | C13: R20 is an editable design input; Rθ = R20 × [1 + α × (θ−20)]. | D13: Values are conservative maximum conductor resistance, not a manufacturer AC-impedance certificate.
A14: Voltage-drop method | B14: IEC-style AC phasor approximation | C14: 3Φ: √3·I·L·(Rcosφ+Xsinφ); 1Φ/DC 2-wire: 2·I·L·(Rcosφ+Xsinφ). | D14: X and temperature must be checked against actual installation, grouping, spacing and cable formation.
A16: Use / design note
A17: This workbook checks voltage drop only. Confirm ampacity, derating, protective-device coordination, short-circuit withstand, earthing/PE conductor, installation method and applicable EIT / owner requirements separately before construction.
A18: Length is one-way route length. For 1Φ and DC 2-wire, the formula already includes the return conductor factor (2).
A19: DC assumptions | B19: Value | C19: Unit / method | D19: Note
A20: Copper temperature coefficient, αCu | B20: 0.00393 | C20: 1/°C | D20: Used to adjust Rdc from 20°C to selected operating temperature.
A21: DC default operating conductor temperature | B21: 90 | C21: °C | D21: Editable in DC Calculator; datasheets allow 120°C for limited duration, but 90°C is the default design point.
A22: DC default Voltage Drop target | B22: 0.03 | C22: % | D22: Editable in DC Calculator; common reference target for PV string cable.
A23: DC design minimum cell temperature | B23: 10 | C23: °C | D23: Editable design assumption used for cold Voc check; confirm project climate and inverter design basis.
A24: Default inverter maximum DC input voltage | B24: 1100 | C24: V DC | D24: Editable design assumption; replace with the selected inverter datasheet value.
A26: DC source / method | B26: Reference | C26: How used | D26: Important limitation
A27: PV module datasheet | B27: 3.2.panel_datasheet_JKM700-725N-66HL5-BDV-Z2C2-OC.pdf | C27: Uses the 725 Wp STC row: Vmp 41.00 V, Imp 17.69 A, Voc 49.20 V, Isc 18.74 A and temperature coefficients. | D27: Confirm the final procurement module and any bifacial design gain separately.
A28: Phelps Dodge PV cable | B28: Phelps_Dodge_PV_Cable_H1Z2Z2-K_Datasheet.pdf | C28: Uses Rdc at 20°C, current-carrying capacities and manufacturer datasheet voltage-drop column where provided. | D28: Verify exact cable construction, installation arrangement, derating and current-carrying method.
A29: Bangkok Cable PV cable | B29: Bangkok_Cable_H1Z2Z2-K_PV_Cable_Datasheet.pdf | C29: Uses Rdc at 20°C and current-carrying capacities from the attached table; operating-temperature VD is formula-calculated. | D29: The attached table does not provide a separate voltage-drop column; confirm final catalogue values if required.
A30: DC voltage-drop method | B30: 2-wire DC; Rθ = R20 × [1 + α × (T−20)] | C30: ΔV = 2 × I × L × Rθ / 1000; Power loss = I² × loop resistance; L is one-way. | D30: Voltage Drop does not replace ampacity/derating, protection, connector, short-circuit or inverter checks.

Sheet Project Cable List
A1: Project Cable List | Extracted Low Voltage CV items
A3: Cable ID used in tool | B3: Original-style source description | C3: Classification | D3: Included?
A4: CV-FD 4C 10 | B4: AC Cable (FD-0.6/1KV-CV 4C) 4C 10 sq.mm. | C4: Low voltage 0.6/1 kV CV | D4: Yes
A5: CV-FD 1C 16 | B5: AC Cable (FD-0.6/1KV-CV 1C) 1C 16 sq.mm. | C5: Low voltage 0.6/1 kV CV | D5: Yes
A6: CV-FD 4C 16 | B6: AC Cable (FD-0.6/1KV-CV 4C) 4C 16 sq.mm. | C6: Low voltage 0.6/1 kV CV | D6: Yes
A7: CV-FD 1C 25 | B7: AC Cable (FD-0.6/1KV-CV 1C) 1C 25 sq.mm. | C7: Low voltage 0.6/1 kV CV | D7: Yes
A8: CV-FD 4C 25 | B8: AC Cable (FD-0.6/1KV-CV 4C) 4C 25 sq.mm. | C8: Low voltage 0.6/1 kV CV | D8: Yes
A9: CV-FD 1C 35 | B9: AC Cable (FD-0.6/1KV-CV 1C) 1C 35 sq.mm. | C9: Low voltage 0.6/1 kV CV | D9: Yes
A10: CV-FD 4C 35 | B10: AC Cable (FD-0.6/1KV-CV 4C) 4C 35 sq.mm. | C10: Low voltage 0.6/1 kV CV | D10: Yes
A11: CV-FD 1C 50 | B11: AC Cable (FD-0.6/1KV-CV 1C) 1C 50 sq.mm. | C11: Low voltage 0.6/1 kV CV | D11: Yes
A12: CV-FD 1C 70 | B12: AC Cable (FD-0.6/1KV-CV 1C) 1C 70 sq.mm. | C12: Low voltage 0.6/1 kV CV | D12: Yes
A13: CV-FD 4C 70 | B13: AC Cable (FD-0.6/1KV-CV 4C) 4C 70 sq.mm. | C13: Low voltage 0.6/1 kV CV | D13: Yes
A14: CV-FD 1C 95 | B14: AC Cable (FD-0.6/1KV-CV 1C) 1C 95 sq.mm. | C14: Low voltage 0.6/1 kV CV | D14: Yes
... A18: CV-FD 1C 240 | B18: AC Cable (FD-0.6/1KV-CV 1C) 1C 240 sq.mm. | C18: Low voltage 0.6/1 kV CV | D18: Yes

Sheet Panel Datasheet
A1: PV Module Datasheet | Jinko JKM700-725N-66HL5-BDV-Z2C2-OC | Selected 725 Wp | B1: PV Module Datasheet | Jinko JKM700-725N-66HL5-BDV-Z2C2-OC | Selected 725 Wp | C1: PV Module Datasheet | Jinko JKM700-725N-66HL5-BDV-Z2C2-OC | Selected 725 Wp | D1: PV Module Datasheet | Jinko JKM700-725N-66HL5-BDV-Z2C2-OC | Selected 725 Wp | E1: PV Module Datasheet | Jinko JKM700-725N-66HL5-BDV-Z2C2-OC | Selected 725 Wp | F1: PV Module Datasheet | Jinko JKM700-725N-66HL5-BDV-Z2C2-OC | Selected 725 Wp | G1: PV Module Datasheet | Jinko JKM700-725N-66HL5-BDV-Z2C2-OC | Selected 725 Wp | H1: PV Module Datasheet | Jinko JKM700-725N-66HL5-BDV-Z2C2-OC | Selected 725 Wp | I1: PV Module Datasheet | Jinko JKM700-725N-66HL5-BDV-Z2C2-OC | Selected 725 Wp | J1: PV Module Datasheet | Jinko JKM700-725N-66HL5-BDV-Z2C2-OC | Selected 725 Wp
A3: Selected module characteristics (STC) | B3: Value | D3: Electrical performance table from datasheet | STC | E3: Electrical performance table from datasheet | STC | F3: Electrical performance table from datasheet | STC | G3: Electrical performance table from datasheet | STC | H3: Electrical performance table from datasheet | STC | I3: Electrical performance table from datasheet | STC | J3: Electrical performance table from datasheet | STC
A4: Model | B4: JKM700-725N-66HL5-BDV-Z2C2-OC | D4: Pmax (Wp) | E4: Vmp (V) | F4: Imp (A) | G4: Voc (V) | H4: Isc (A) | I4: Efficiency | J4: Selection
A5: Selected Pmax (Wp) | B5: 725 | D5: 700 | E5: 40.42 | F5: 17.32 | G5: 48.4 | H5: 18.4 | I5: 0.2254
A6: Vmp at STC (V) | B6: 41 | D6: 705 | E6: 40.53 | F6: 17.4 | G6: 48.56 | H6: 18.46 | I6: 0.227
A7: Imp at STC (A) | B7: 17.69 | D7: 710 | E7: 40.65 | F7: 17.47 | G7: 48.73 | H7: 18.53 | I7: 0.2286
A8: Voc at STC (V) | B8: 49.2 | D8: 715 | E8: 40.77 | F8: 17.54 | G8: 48.88 | H8: 18.6 | I8: 0.2302
A9: Isc at STC (A) | B9: 18.74 | D9: 720 | E9: 40.89 | F9: 17.61 | G9: 49.04 | H9: 18.67 | I9: 0.2318
A10: Module efficiency | B10: 0.2335 | D10: 725 | E10: 41 | F10: 17.69 | G10: 49.2 | H10: 18.74 | I10: 0.2335 | J10: SELECTED
A11: Maximum system voltage (V DC) | B11: 1500
A12: Maximum series fuse rating (A) | B12: 35 | D12: Design note: calculator uses STC electrical values for Voltage Drop and a separate minimum-cell-temperature check for Voc. | E12: Design note: calculator uses STC electrical values for Voltage Drop and a separate minimum-cell-temperature check for Voc. | F12: Design note: calculator uses STC electrical values for Voltage Drop and a separate minimum-cell-temperature check for Voc. | G12: Design note: calculator uses STC electrical values for Voltage Drop and a separate minimum-cell-temperature check for Voc. | H12: Design note: calculator uses STC electrical values for Voltage Drop and a separate minimum-cell-temperature check for Voc. | I12: Design note: calculator uses STC electrical values for Voltage Drop and a separate minimum-cell-temperature check for Voc. | J12: Design note: calculator uses STC electrical values for Voltage Drop and a separate minimum-cell-temperature check for Voc.
A13: Temperature coefficient Pmax | B13: -0.0029
A14: Temperature coefficient Voc | B14: -0.0025 | D14: STC: irradiance 1000 W/m², cell temperature 25 °C, AM 1.5. Datasheet notes power measurement tolerance ±3%. | E14: STC: irradiance 1000 W/m², cell temperature 25 °C, AM 1.5. Datasheet notes power measurement tolerance ±3%. | F14: STC: irradiance 1000 W/m², cell temperature 25 °C, AM 1.5. Datasheet notes power measurement tolerance ±3%. | G14: STC: irradiance 1000 W/m², cell temperature 25 °C, AM 1.5. Datasheet notes power measurement tolerance ±3%. | H14: STC: irradiance 1000 W/m², cell temperature 25 °C, AM 1.5. Datasheet notes power measurement tolerance ±3%. | I14: STC: irradiance 1000 W/m², cell temperature 25 °C, AM 1.5. Datasheet notes power measurement tolerance ±3%. | J14: STC: irradiance 1000 W/m², cell temperature 25 °C, AM 1.5. Datasheet notes power measurement tolerance ±3%.
A15: Temperature coefficient Isc | B15: 0.00045
A16: Operating temperature | B16: -40 °C to +70 °C
A17: Cell technology | B17: N-type mono-crystalline, bifacial, dual glass
A18: Dimensions | B18: 2384 × 1303 × 33 mm
A19: Weight | B19: 37.5 kg
A20: Output cables | B20: 4.0 mm²; (+) 400 mm, (-) 200 mm or customized
A21: Connector | B21: PV-JK03M/xy, PV-03M2/xy; PV-KST4-EVO2A/xy, PV-KBT4-EVO2A/xy
A22: Source file | B22: 3.2.panel_datasheet_JKM700-725N-66HL5-BDV-Z2C2-OC.pdf

Sheet Cable Database
A1: Cable Database | Low-voltage CV in project list
A3: Cable ID | B3: Project description | C3: No. cores | D3: Area (sq.mm.) | E3: Rdc @20°C (Ω/km) | F3: α (1/°C) | G3: R @ selected temp (Ω/km) | H3: X default (Ω/km) | I3: Cable status | J3: Source
A4: CV-FD 4C 10 | B4: FD-0.6/1KV-CV 4C | C4: 4 | D4: 10 | E4: 1.83 | F4: ='Assumptions & Sources'!$B$4 -> 0.00393 | G4: =E4*(1+F4*('Assumptions & Sources'!$B$5-'Assumptions & Sources'!$B$8)) -> 2.333433 | H4: ='Assumptions & Sources'!$B$7 -> 0.08 | I4: Included in source file | J4: Project list + IEC 60228 Rdc
A5: CV-FD 1C 16 | B5: FD-0.6/1KV-CV 1C | C5: 1 | D5: 16 | E5: 1.15 | F5: ='Assumptions & Sources'!$B$4 -> 0.00393 | G5: =E5*(1+F5*('Assumptions & Sources'!$B$5-'Assumptions & Sources'!$B$8)) -> 1.466365 | H5: ='Assumptions & Sources'!$B$7 -> 0.08 | I5: Included in source file | J5: Project list + IEC 60228 Rdc
A6: CV-FD 4C 16 | B6: FD-0.6/1KV-CV 4C | C6: 4 | D6: 16 | E6: 1.15 | F6: ='Assumptions & Sources'!$B$4 -> 0.00393 | G6: =E6*(1+F6*('Assumptions & Sources'!$B$5-'Assumptions & Sources'!$B$8)) -> 1.466365 | H6: ='Assumptions & Sources'!$B$7 -> 0.08 | I6: Included in source file | J6: Project list + IEC 60228 Rdc
A7: CV-FD 1C 25 | B7: FD-0.6/1KV-CV 1C | C7: 1 | D7: 25 | E7: 0.727 | F7: ='Assumptions & Sources'!$B$4 -> 0.00393 | G7: =E7*(1+F7*('Assumptions & Sources'!$B$5-'Assumptions & Sources'!$B$8)) -> 0.9269977 | H7: ='Assumptions & Sources'!$B$7 -> 0.08 | I7: Included in source file | J7: Project list + IEC 60228 Rdc
A8: CV-FD 4C 25 | B8: FD-0.6/1KV-CV 4C | C8: 4 | D8: 25 | E8: 0.727 | F8: ='Assumptions & Sources'!$B$4 -> 0.00393 | G8: =E8*(1+F8*('Assumptions & Sources'!$B$5-'Assumptions & Sources'!$B$8)) -> 0.9269977 | H8: ='Assumptions & Sources'!$B$7 -> 0.08 | I8: Included in source file | J8: Project list + IEC 60228 Rdc
A9: CV-FD 1C 35 | B9: FD-0.6/1KV-CV 1C | C9: 1 | D9: 35 | E9: 0.524 | F9: ='Assumptions & Sources'!$B$4 -> 0.00393 | G9: =E9*(1+F9*('Assumptions & Sources'!$B$5-'Assumptions & Sources'!$B$8)) -> 0.6681524 | H9: ='Assumptions & Sources'!$B$7 -> 0.08 | I9: Included in source file | J9: Project list + IEC 60228 Rdc
A10: CV-FD 4C 35 | B10: FD-0.6/1KV-CV 4C | C10: 4 | D10: 35 | E10: 0.524 | F10: ='Assumptions & Sources'!$B$4 -> 0.00393 | G10: =E10*(1+F10*('Assumptions & Sources'!$B$5-'Assumptions & Sources'!$B$8)) -> 0.6681524 | H10: ='Assumptions & Sources'!$B$7 -> 0.08 | I10: Included in source file | J10: Project list + IEC 60228 Rdc
A11: CV-FD 1C 50 | B11: FD-0.6/1KV-CV 1C | C11: 1 | D11: 50 | E11: 0.387 | F11: ='Assumptions & Sources'!$B$4 -> 0.00393 | G11: =E11*(1+F11*('Assumptions & Sources'!$B$5-'Assumptions & Sources'!$B$8)) -> 0.4934637 | H11: ='Assumptions & Sources'!$B$7 -> 0.08 | I11: Included in source file | J11: Project list + IEC 60228 Rdc
A12: CV-FD 1C 70 | B12: FD-0.6/1KV-CV 1C | C12: 1 | D12: 70 | E12: 0.268 | F12: ='Assumptions & Sources'!$B$4 -> 0.00393 | G12: =E12*(1+F12*('Assumptions & Sources'!$B$5-'Assumptions & Sources'!$B$8)) -> 0.3417268 | H12: ='Assumptions & Sources'!$B$7 -> 0.08 | I12: Included in source file | J12: Project list + IEC 60228 Rdc
A13: CV-FD 4C 70 | B13: FD-0.6/1KV-CV 4C | C13: 4 | D13: 70 | E13: 0.268 | F13: ='Assumptions & Sources'!$B$4 -> 0.00393 | G13: =E13*(1+F13*('Assumptions & Sources'!$B$5-'Assumptions & Sources'!$B$8)) -> 0.3417268 | H13: ='Assumptions & Sources'!$B$7 -> 0.08 | I13: Included in source file | J13: Project list + IEC 60228 Rdc
A14: CV-FD 1C 95 | B14: FD-0.6/1KV-CV 1C | C14: 1 | D14: 95 | E14: 0.193 | F14: ='Assumptions & Sources'!$B$4 -> 0.00393 | G14: =E14*(1+F14*('Assumptions & Sources'!$B$5-'Assumptions & Sources'!$B$8)) -> 0.2460943 | H14: ='Assumptions & Sources'!$B$7 -> 0.08 | I14: Included in source file | J14: Project list + IEC 60228 Rdc
A15: CV-FD 1C 120 | B15: FD-0.6/1KV-CV 1C | C15: 1 | D15: 120 | E15: 0.153 | F15: ='Assumptions & Sources'!$B$4 -> 0.00393 | G15: =E15*(1+F15*('Assumptions & Sources'!$B$5-'Assumptions & Sources'!$B$8)) -> 0.1950903 | H15: ='Assumptions & Sources'!$B$7 -> 0.08 | I15: Included in source file | J15: Project list + IEC 60228 Rdc
... A18: CV-FD 1C 240 | B18: FD-0.6/1KV-CV 1C | C18: 1 | D18: 240 | E18: 0.0754 | F18: ='Assumptions & Sources'!$B$4 -> 0.00393 | G18: =E18*(1+F18*('Assumptions & Sources'!$B$5-'Assumptions & Sources'!$B$8)) -> 0.09614254 | H18: ='Assumptions & Sources'!$B$7 -> 0.08 | I18: Included in source file | J18: Project list + IEC 60228 Rdc

Sheet DC Cable Database
A1: DC Cable Database | H1Z2Z2-K PV Cable | Phelps Dodge and Bangkok Cable | B1: DC Cable Database | H1Z2Z2-K PV Cable | Phelps Dodge and Bangkok Cable | C1: DC Cable Database | H1Z2Z2-K PV Cable | Phelps Dodge and Bangkok Cable | D1: DC Cable Database | H1Z2Z2-K PV Cable | Phelps Dodge and Bangkok Cable | E1: DC Cable Database | H1Z2Z2-K PV Cable | Phelps Dodge and Bangkok Cable | F1: DC Cable Database | H1Z2Z2-K PV Cable | Phelps Dodge and Bangkok Cable | G1: DC Cable Database | H1Z2Z2-K PV Cable | Phelps Dodge and Bangkok Cable | H1: DC Cable Database | H1Z2Z2-K PV Cable | Phelps Dodge and Bangkok Cable | I1: DC Cable Database | H1Z2Z2-K PV Cable | Phelps Dodge and Bangkok Cable | J1: DC Cable Database | H1Z2Z2-K PV Cable | Phelps Dodge and Bangkok Cable | K1: DC Cable Database | H1Z2Z2-K PV Cable | Phelps Dodge and Bangkok Cable | L1: DC Cable Database | H1Z2Z2-K PV Cable | Phelps Dodge and Bangkok Cable | M1: DC Cable Database | H1Z2Z2-K PV Cable | Phelps Dodge and Bangkok Cable | N1: DC Cable Database | H1Z2Z2-K PV Cable | Phelps Dodge and Bangkok Cable | O1: DC Cable Database | H1Z2Z2-K PV Cable | Phelps Dodge and Bangkok Cable
A2: Resistance values are datasheet maximum DC resistance at 20 °C. Rdc @ operating temp and loop mV/A/m are formula-driven using the selected operating temperature and αCu. | M2: ='DC Calculator'!B10 -> 90
A3: Cable ID | B3: Manufacturer | C3: Cable type | D3: Area (mm²) | E3: Rdc @20°C (Ω/km) | F3: Datasheet VD (mV/A/m) | G3: Ampacity free air (A) | H3: Ampacity surface (A) | I3: Ampacity two loaded / surface (A) | J3: Rated voltage DC (kV) | K3: Max conductor temp (°C) | L3: Standard length (m) | M3: Rdc @ operating temp (Ω/km) | N3: Loop VD @ operating temp (mV/A/m) | O3: Source / note
A4: Phelps Dodge H1Z2Z2-K 2.5 mm² | B4: Phelps Dodge | C4: H1Z2Z2-K | D4: 2.5 | E4: 8.21 | F4: 20.94 | G4: 41 | H4: 39 | I4: 33 | J4: 1.5 | K4: 120 | L4: 200 | M4: =E4*(1+'Assumptions & Sources'!$B$20*('DC Calculator'!$B$10-'Assumptions & Sources'!$B$8)) -> 10.468571 | N4: =2*M4 -> 20.937142 | O4: Phelps_Dodge_PV_Cable_H1Z2Z2-K_Datasheet.pdf; datasheet VD column
A5: Phelps Dodge H1Z2Z2-K 4 mm² | B5: Phelps Dodge | C5: H1Z2Z2-K | D5: 4 | E5: 5.09 | F5: 12.98 | G5: 55 | H5: 52 | I5: 44 | J5: 1.5 | K5: 120 | L5: 200 | M5: =E5*(1+'Assumptions & Sources'!$B$20*('DC Calculator'!$B$10-'Assumptions & Sources'!$B$8)) -> 6.490259 | N5: =2*M5 -> 12.980518 | O5: Phelps_Dodge_PV_Cable_H1Z2Z2-K_Datasheet.pdf; datasheet VD column
A6: Phelps Dodge H1Z2Z2-K 6 mm² | B6: Phelps Dodge | C6: H1Z2Z2-K | D6: 6 | E6: 3.39 | F6: 8.65 | G6: 70 | H6: 67 | I6: 57 | J6: 1.5 | K6: 120 | L6: 100 | M6: =E6*(1+'Assumptions & Sources'!$B$20*('DC Calculator'!$B$10-'Assumptions & Sources'!$B$8)) -> 4.322589 | N6: =2*M6 -> 8.645178 | O6: Phelps_Dodge_PV_Cable_H1Z2Z2-K_Datasheet.pdf; datasheet VD column
A7: Phelps Dodge H1Z2Z2-K 10 mm² | B7: Phelps Dodge | C7: H1Z2Z2-K | D7: 10 | E7: 1.95 | F7: 4.97 | G7: 98 | H7: 93 | I7: 79 | J7: 1.5 | K7: 120 | L7: 100 | M7: =E7*(1+'Assumptions & Sources'!$B$20*('DC Calculator'!$B$10-'Assumptions & Sources'!$B$8)) -> 2.486445 | N7: =2*M7 -> 4.97289 | O7: Phelps_Dodge_PV_Cable_H1Z2Z2-K_Datasheet.pdf; datasheet VD column
A8: Phelps Dodge H1Z2Z2-K 16 mm² | B8: Phelps Dodge | C8: H1Z2Z2-K | D8: 16 | E8: 1.24 | F8: 3.16 | G8: 132 | H8: 125 | I8: 107 | J8: 1.5 | K8: 120 | L8: 100 | M8: =E8*(1+'Assumptions & Sources'!$B$20*('DC Calculator'!$B$10-'Assumptions & Sources'!$B$8)) -> 1.581124 | N8: =2*M8 -> 3.162248 | O8: Phelps_Dodge_PV_Cable_H1Z2Z2-K_Datasheet.pdf; datasheet VD column
A9: Phelps Dodge H1Z2Z2-K 25 mm² | B9: Phelps Dodge | C9: H1Z2Z2-K | D9: 25 | E9: 0.795 | F9: 2.03 | G9: 176 | H9: 167 | I9: 142 | J9: 1.5 | K9: 120 | L9: 100 | M9: =E9*(1+'Assumptions & Sources'!$B$20*('DC Calculator'!$B$10-'Assumptions & Sources'!$B$8)) -> 1.0137045 | N9: =2*M9 -> 2.027409 | O9: Phelps_Dodge_PV_Cable_H1Z2Z2-K_Datasheet.pdf; datasheet VD column
A10: Phelps Dodge H1Z2Z2-K 35 mm² | B10: Phelps Dodge | C10: H1Z2Z2-K | D10: 35 | E10: 0.565 | F10: 1.44 | G10: 218 | H10: 207 | I10: 176 | J10: 1.5 | K10: 120 | L10: 100 | M10: =E10*(1+'Assumptions & Sources'!$B$20*('DC Calculator'!$B$10-'Assumptions & Sources'!$B$8)) -> 0.7204315 | N10: =2*M10 -> 1.440863 | O10: Phelps_Dodge_PV_Cable_H1Z2Z2-K_Datasheet.pdf; datasheet VD column
A11: Phelps Dodge H1Z2Z2-K 50 mm² | B11: Phelps Dodge | C11: H1Z2Z2-K | D11: 50 | E11: 0.393 | F11: 1 | G11: 276 | H11: 262 | I11: 221 | J11: 1.5 | K11: 120 | L11: 100 | M11: =E11*(1+'Assumptions & Sources'!$B$20*('DC Calculator'!$B$10-'Assumptions & Sources'!$B$8)) -> 0.5011143 | N11: =2*M11 -> 1.0022286 | O11: Phelps_Dodge_PV_Cable_H1Z2Z2-K_Datasheet.pdf; datasheet VD column
A12: Phelps Dodge H1Z2Z2-K 70 mm² | B12: Phelps Dodge | C12: H1Z2Z2-K | D12: 70 | E12: 0.277 | F12: 0.71 | G12: 347 | H12: 330 | I12: 278 | J12: 1.5 | K12: 120 | L12: 500 | M12: =E12*(1+'Assumptions & Sources'!$B$20*('DC Calculator'!$B$10-'Assumptions & Sources'!$B$8)) -> 0.3532027 | N12: =2*M12 -> 0.7064054 | O12: Phelps_Dodge_PV_Cable_H1Z2Z2-K_Datasheet.pdf; datasheet VD column
A13: Phelps Dodge H1Z2Z2-K 95 mm² | B13: Phelps Dodge | C13: H1Z2Z2-K | D13: 95 | E13: 0.21 | F13: 0.54 | G13: 416 | H13: 395 | I13: 333 | J13: 1.5 | K13: 120 | L13: 500 | M13: =E13*(1+'Assumptions & Sources'!$B$20*('DC Calculator'!$B$10-'Assumptions & Sources'!$B$8)) -> 0.267771 | N13: =2*M13 -> 0.535542 | O13: Phelps_Dodge_PV_Cable_H1Z2Z2-K_Datasheet.pdf; datasheet VD column
A14: Phelps Dodge H1Z2Z2-K 120 mm² | B14: Phelps Dodge | C14: H1Z2Z2-K | D14: 120 | E14: 0.164 | F14: 0.42 | G14: 488 | H14: 464 | I14: 390 | J14: 1.5 | K14: 120 | L14: 500 | M14: =E14*(1+'Assumptions & Sources'!$B$20*('DC Calculator'!$B$10-'Assumptions & Sources'!$B$8)) -> 0.2091164 | N14: =2*M14 -> 0.4182328 | O14: Phelps_Dodge_PV_Cable_H1Z2Z2-K_Datasheet.pdf; datasheet VD column
A15: Phelps Dodge H1Z2Z2-K 150 mm² | B15: Phelps Dodge | C15: H1Z2Z2-K | D15: 150 | E15: 0.132 | F15: 0.34 | G15: 566 | H15: 538 | I15: 453 | J15: 1.5 | K15: 120 | L15: 500 | M15: =E15*(1+'Assumptions & Sources'!$B$20*('DC Calculator'!$B$10-'Assumptions & Sources'!$B$8)) -> 0.1683132 | N15: =2*M15 -> 0.3366264 | O15: Phelps_Dodge_PV_Cable_H1Z2Z2-K_Datasheet.pdf; datasheet VD column
... A17: Phelps Dodge H1Z2Z2-K 240 mm² | B17: Phelps Dodge | C17: H1Z2Z2-K | D17: 240 | E17: 0.0817 | F17: 0.21 | G17: 775 | H17: 736 | I17: 620 | J17: 1.5 | K17: 120 | L17: 500 | M17: =E17*(1+'Assumptions & Sources'!$B$20*('DC Calculator'!$B$10-'Assumptions & Sources'!$B$8)) -> 0.10417567 | N17: =2*M17 -> 0.20835134 | O17: Phelps_Dodge_PV_Cable_H1Z2Z2-K_Datasheet.pdf; datasheet VD column
A18: Bangkok Cable H1Z2Z2-K 1.5 mm² | B18: Bangkok Cable | C18: H1Z2Z2-K | D18: 1.5 | E18: 13.7 | G18: 30 | H18: 29 | I18: 24 | J18: 1.5 | K18: 120 | L18: 200 | M18: =E18*(1+'Assumptions & Sources'!$B$20*('DC Calculator'!$B$10-'Assumptions & Sources'!$B$8)) -> 17.46887 | N18: =2*M18 -> 34.93774 | O18: Bangkok_Cable_H1Z2Z2-K_PV_Cable_Datasheet.pdf; attached table
A19: Bangkok Cable H1Z2Z2-K 2.5 mm² | B19: Bangkok Cable | C19: H1Z2Z2-K | D19: 2.5 | E19: 8.21 | G19: 41 | H19: 39 | I19: 33 | J19: 1.5 | K19: 120 | L19: 200 | M19: =E19*(1+'Assumptions & Sources'!$B$20*('DC Calculator'!$B$10-'Assumptions & Sources'!$B$8)) -> 10.468571 | N19: =2*M19 -> 20.937142 | O19: Bangkok_Cable_H1Z2Z2-K_PV_Cable_Datasheet.pdf; attached table
A20: Bangkok Cable H1Z2Z2-K 4 mm² | B20: Bangkok Cable | C20: H1Z2Z2-K | D20: 4 | E20: 5.09 | G20: 55 | H20: 52 | I20: 44 | J20: 1.5 | K20: 120 | L20: 200 | M20: =E20*(1+'Assumptions & Sources'!$B$20*('DC Calculator'!$B$10-'Assumptions & Sources'!$B$8)) -> 6.490259 | N20: =2*M20 -> 12.980518 | O20: Bangkok_Cable_H1Z2Z2-K_PV_Cable_Datasheet.pdf; attached table
A21: Bangkok Cable H1Z2Z2-K 6 mm² | B21: Bangkok Cable | C21: H1Z2Z2-K | D21: 6 | E21: 3.39 | G21: 70 | H21: 67 | I21: 57 | J21: 1.5 | K21: 120 | L21: 100 | M21: =E21*(1+'Assumptions & Sources'!$B$20*('DC Calculator'!$B$10-'Assumptions & Sources'!$B$8)) -> 4.322589 | N21: =2*M21 -> 8.645178 | O21: Bangkok_Cable_H1Z2Z2-K_PV_Cable_Datasheet.pdf; attached table
A22: Bangkok Cable H1Z2Z2-K 10 mm² | B22: Bangkok Cable | C22: H1Z2Z2-K | D22: 10 | E22: 1.95 | G22: 98 | H22: 93 | I22: 79 | J22: 1.5 | K22: 120 | L22: 100 | M22: =E22*(1+'Assumptions & Sources'!$B$20*('DC Calculator'!$B$10-'Assumptions & Sources'!$B$8)) -> 2.486445 | N22: =2*M22 -> 4.97289 | O22: Bangkok_Cable_H1Z2Z2-K_PV_Cable_Datasheet.pdf; attached table
A23: Bangkok Cable H1Z2Z2-K 16 mm² | B23: Bangkok Cable | C23: H1Z2Z2-K | D23: 16 | E23: 1.24 | G23: 132 | H23: 125 | I23: 107 | J23: 1.5 | K23: 120 | L23: 100 | M23: =E23*(1+'Assumptions & Sources'!$B$20*('DC Calculator'!$B$10-'Assumptions & Sources'!$B$8)) -> 1.581124 | N23: =2*M23 -> 3.162248 | O23: Bangkok_Cable_H1Z2Z2-K_PV_Cable_Datasheet.pdf; attached table
A24: Bangkok Cable H1Z2Z2-K 25 mm² | B24: Bangkok Cable | C24: H1Z2Z2-K | D24: 25 | E24: 0.795 | G24: 176 | H24: 167 | I24: 142 | J24: 1.5 | K24: 120 | L24: 100 | M24: =E24*(1+'Assumptions & Sources'!$B$20*('DC Calculator'!$B$10-'Assumptions & Sources'!$B$8)) -> 1.0137045 | N24: =2*M24 -> 2.027409 | O24: Bangkok_Cable_H1Z2Z2-K_PV_Cable_Datasheet.pdf; attached table
A25: Bangkok Cable H1Z2Z2-K 35 mm² | B25: Bangkok Cable | C25: H1Z2Z2-K | D25: 35 | E25: 0.565 | G25: 218 | H25: 207 | I25: 176 | J25: 1.5 | K25: 120 | L25: 100 | M25: =E25*(1+'Assumptions & Sources'!$B$20*('DC Calculator'!$B$10-'Assumptions & Sources'!$B$8)) -> 0.7204315 | N25: =2*M25 -> 1.440863 | O25: Bangkok_Cable_H1Z2Z2-K_PV_Cable_Datasheet.pdf; attached table
A26: Bangkok Cable H1Z2Z2-K 50 mm² | B26: Bangkok Cable | C26: H1Z2Z2-K | D26: 50 | E26: 0.393 | G26: 276 | H26: 262 | I26: 221 | J26: 1.5 | K26: 120 | L26: 100 | M26: =E26*(1+'Assumptions & Sources'!$B$20*('DC Calculator'!$B$10-'Assumptions & Sources'!$B$8)) -> 0.5011143 | N26: =2*M26 -> 1.0022286 | O26: Bangkok_Cable_H1Z2Z2-K_PV_Cable_Datasheet.pdf; attached table
A27: Bangkok Cable H1Z2Z2-K 70 mm² | B27: Bangkok Cable | C27: H1Z2Z2-K | D27: 70 | E27: 0.277 | G27: 347 | H27: 330 | I27: 278 | J27: 1.5 | K27: 120 | L27: 500 | M27: =E27*(1+'Assumptions & Sources'!$B$20*('DC Calculator'!$B$10-'Assumptions & Sources'!$B$8)) -> 0.3532027 | N27: =2*M27 -> 0.7064054 | O27: Bangkok_Cable_H1Z2Z2-K_PV_Cable_Datasheet.pdf; attached table
A28: Bangkok Cable H1Z2Z2-K 95 mm² | B28: Bangkok Cable | C28: H1Z2Z2-K | D28: 95 | E28: 0.21 | G28: 416 | H28: 395 | I28: 333 | J28: 1.5 | K28: 120 | L28: 500 | M28: =E28*(1+'Assumptions & Sources'!$B$20*('DC Calculator'!$B$10-'Assumptions & Sources'!$B$8)) -> 0.267771 | N28: =2*M28 -> 0.535542 | O28: Bangkok_Cable_H1Z2Z2-K_PV_Cable_Datasheet.pdf; attached table
A29: Bangkok Cable H1Z2Z2-K 120 mm² | B29: Bangkok Cable | C29: H1Z2Z2-K | D29: 120 | E29: 0.164 | G29: 488 | H29: 464 | I29: 390 | J29: 1.5 | K29: 120 | L29: 500 | M29: =E29*(1+'Assumptions & Sources'!$B$20*('DC Calculator'!$B$10-'Assumptions & Sources'!$B$8)) -> 0.2091164 | N29: =2*M29 -> 0.4182328 | O29: Bangkok_Cable_H1Z2Z2-K_PV_Cable_Datasheet.pdf; attached table
... A32: Bangkok Cable H1Z2Z2-K 240 mm² | B32: Bangkok Cable | C32: H1Z2Z2-K | D32: 240 | E32: 0.0817 | G32: 775 | H32: 736 | I32: 620 | J32: 1.5 | K32: 120 | L32: 500 | M32: =E32*(1+'Assumptions & Sources'!$B$20*('DC Calculator'!$B$10-'Assumptions & Sources'!$B$8)) -> 0.10417567 | N32: =2*M32 -> 0.20835134 | O32: Bangkok_Cable_H1Z2Z2-K_PV_Cable_Datasheet.pdf; attached table

Sheet AC Calculator
A1: CV Low-Voltage Voltage-Drop Calculator | Design limit ≤ 3%
A3: 1) Enter or select yellow cells. Results update automatically. All lengths are one-way route lengths.
A5: INPUT | B5: VALUE | D5: 2) Calculated result
A6: Cable ID | B6: CV-FD 1C 70 | D6: Rdc @20°C (Ω/km) | E6: =VLOOKUP(B6,'Cable Database'!$A$4:$J$18,5,FALSE) -> 0.268
A7: System | B7: 3Φ AC | D7: R at operating temp (Ω/km) | E7: =E6*(1+'Assumptions & Sources'!$B$4*(B13-'Assumptions & Sources'!$B$8)) -> 0.3417268
A8: Nominal voltage (V) | B8: 400 | D8: sin φ | E8: =SQRT(MAX(0,1-B10^2)) -> 0.52678269
A9: Load current (A) | B9: 100 | D9: Circuit multiplier | E9: =IF(B7="3Φ AC",SQRT(3),2) -> 1.7320508
A10: Power factor (AC only) | B10: 0.85 | D10: Effective impedance term (Ω/km) | E10: =IF(B7="DC 2-wire",E7,E7*B10+B14*E8) -> 0.3326104
A11: One-way route length (m) | B11: 100 | D11: Voltage drop ΔV (V) | E11: =E9*B9*B11/1000*E10 -> 5.760981
A12: Voltage-drop limit | B12: 0.03 | D12: Voltage drop | E12: =E11/B8 -> 0.014402453
A13: Conductor temperature (°C) | B13: 90 | D13: Result | E13: =IF(E12<=B12,"PASS ≤ limit","FAIL > limit") -> PASS ≤ limit
A14: Reactance X (Ω/km) | B14: 0.08 | D14: Maximum route length (m) | E14: =B8*B12*1000/(E9*B9*E10) -> 208.29786
A15: Notes / circuit name | B15: Example: LV feeder | D15: Margin to limit (m) | E15: =E14-B11 -> 108.29786
D16: Formula used | E16: =IF(B7="3Φ AC","√3×I×L×(Rcosφ+Xsinφ)",IF(B7="1Φ AC","2×I×L×(Rcosφ+Xsinφ)","2×I×L×R")) -> √3×I×L×(Rcosφ+Xsinφ)
A18: Important: This is a voltage-drop check, not a cable ampacity selection. Verify ampacity/derating, fault duty, protection and EIT/project requirements separately.
A22: ขั้นตอนการเลือกสาย ยังไม่ได้รวมในนี้
A23: 1) ชนิดสาย
A24: 2) กลุ่มการติดตั้ง
A25: 3) Factor จำนวนสายไฟ
A26: 4) Factor อุณหภูมิสภาพแวดล้อม
A27: 5) ใช้ R จากผู้ผลิตคำนวณ Voltage Drop

Sheet AC Quick Reference
A1: Quick Reference | Maximum one-way route length for voltage drop ≤ limit
A3: Common inputs | B3: Value | D3: Preset scenarios (change current / PF / voltage in the header cells as needed) | E3: Preset scenarios (change current / PF / voltage in the header cells as needed) | F3: Preset scenarios (change current / PF / voltage in the header cells as needed) | G3: Preset scenarios (change current / PF / voltage in the header cells as needed) | H3: Preset scenarios (change current / PF / voltage in the header cells as needed) | I3: Preset scenarios (change current / PF / voltage in the header cells as needed) | J3: Preset scenarios (change current / PF / voltage in the header cells as needed) | K3: Preset scenarios (change current / PF / voltage in the header cells as needed)
A4: Voltage-drop limit | B4: 0.03
A5: Conductor temperature (°C) | B5: 90 | K5: 3 Phase
F6: 3 Phase | G6: 3 Phase | H6: 3 Phase | I6: 1 Phase (AC) | J6: 1 Phase (DC) | K6: เอา Amp ไปหาร จะได้ L-MAX
A7: Cable ID | B7: Cores | C7: Area (sq.mm.) | D7: R at temp (Ω/km) | E7: X (Ω/km) | F7: 3Φ 400V PF 0.80 @100A | G7: 3Φ 400V PF 0.95 @100A | H7: 3Φ 400V PF 1.00 @100A | I7: 1Φ 230V PF 0.95 @50A | J7: DC 1000V @100A | K7: m per A: 3Φ 400V PF1
A8: ='Cable Database'!A4 -> CV-FD 4C 10 | B8: ='Cable Database'!C4 -> 4 | C8: ='Cable Database'!D4 -> 10 | D8: ='Cable Database'!E4*(1+'Assumptions & Sources'!$B$4*($B$5-'Assumptions & Sources'!$B$8)) -> 2.333433 | E8: ='Cable Database'!H4 -> 0.08 | F8: =400*$B$4*1000/(SQRT(3)*100*(D8*0.8+E8*SQRT(1-0.8^2))) -> 36.183399 | G8: =400*$B$4*1000/(SQRT(3)*100*(D8*0.95+E8*SQRT(1-0.95^2))) -> 30.905453 | H8: =400*$B$4*1000/(SQRT(3)*100*D8) -> 29.691031 | I8: =230*$B$4*1000/(2*50*(D8*0.95+E8*SQRT(1-0.95^2))) -> 30.779644 | J8: =1000*$B$4*1000/(2*100*D8) -> 64.282968 | K8: =400*$B$4*1000/(SQRT(3)*(D8)) -> 2969.1031
A9: ='Cable Database'!A5 -> CV-FD 1C 16 | B9: ='Cable Database'!C5 -> 1 | C9: ='Cable Database'!D5 -> 16 | D9: ='Cable Database'!E5*(1+'Assumptions & Sources'!$B$4*($B$5-'Assumptions & Sources'!$B$8)) -> 1.466365 | E9: ='Cable Database'!H5 -> 0.08 | F9: =400*$B$4*1000/(SQRT(3)*100*(D9*0.8+E9*SQRT(1-0.8^2))) -> 56.737766 | G9: =400*$B$4*1000/(SQRT(3)*100*(D9*0.95+E9*SQRT(1-0.95^2))) -> 48.858058 | H9: =400*$B$4*1000/(SQRT(3)*100*D9) -> 47.247467 | I9: =230*$B$4*1000/(2*50*(D9*0.95+E9*SQRT(1-0.95^2))) -> 48.659167 | J9: =1000*$B$4*1000/(2*100*D9) -> 102.29377 | K9: =400*$B$4*1000/(SQRT(3)*(D9)) -> 4724.7467
A10: ='Cable Database'!A6 -> CV-FD 4C 16 | B10: ='Cable Database'!C6 -> 4 | C10: ='Cable Database'!D6 -> 16 | D10: ='Cable Database'!E6*(1+'Assumptions & Sources'!$B$4*($B$5-'Assumptions & Sources'!$B$8)) -> 1.466365 | E10: ='Cable Database'!H6 -> 0.08 | F10: =400*$B$4*1000/(SQRT(3)*100*(D10*0.8+E10*SQRT(1-0.8^2))) -> 56.737766 | G10: =400*$B$4*1000/(SQRT(3)*100*(D10*0.95+E10*SQRT(1-0.95^2))) -> 48.858058 | H10: =400*$B$4*1000/(SQRT(3)*100*D10) -> 47.247467 | I10: =230*$B$4*1000/(2*50*(D10*0.95+E10*SQRT(1-0.95^2))) -> 48.659167 | J10: =1000*$B$4*1000/(2*100*D10) -> 102.29377 | K10: =400*$B$4*1000/(SQRT(3)*(D10)) -> 4724.7467
A11: ='Cable Database'!A7 -> CV-FD 1C 25 | B11: ='Cable Database'!C7 -> 1 | C11: ='Cable Database'!D7 -> 25 | D11: ='Cable Database'!E7*(1+'Assumptions & Sources'!$B$4*($B$5-'Assumptions & Sources'!$B$8)) -> 0.9269977 | E11: ='Cable Database'!H7 -> 0.08 | F11: =400*$B$4*1000/(SQRT(3)*100*(D11*0.8+E11*SQRT(1-0.8^2))) -> 87.743406 | G11: =400*$B$4*1000/(SQRT(3)*100*(D11*0.95+E11*SQRT(1-0.95^2))) -> 76.501662 | H11: =400*$B$4*1000/(SQRT(3)*100*D11) -> 74.738084 | I11: =230*$B$4*1000/(2*50*(D11*0.95+E11*SQRT(1-0.95^2))) -> 76.19024 | J11: =1000*$B$4*1000/(2*100*D11) -> 161.8127 | K11: =400*$B$4*1000/(SQRT(3)*(D11)) -> 7473.8084
A12: ='Cable Database'!A8 -> CV-FD 4C 25 | B12: ='Cable Database'!C8 -> 4 | C12: ='Cable Database'!D8 -> 25 | D12: ='Cable Database'!E8*(1+'Assumptions & Sources'!$B$4*($B$5-'Assumptions & Sources'!$B$8)) -> 0.9269977 | E12: ='Cable Database'!H8 -> 0.08 | F12: =400*$B$4*1000/(SQRT(3)*100*(D12*0.8+E12*SQRT(1-0.8^2))) -> 87.743406 | G12: =400*$B$4*1000/(SQRT(3)*100*(D12*0.95+E12*SQRT(1-0.95^2))) -> 76.501662 | H12: =400*$B$4*1000/(SQRT(3)*100*D12) -> 74.738084 | I12: =230*$B$4*1000/(2*50*(D12*0.95+E12*SQRT(1-0.95^2))) -> 76.19024 | J12: =1000*$B$4*1000/(2*100*D12) -> 161.8127 | K12: =400*$B$4*1000/(SQRT(3)*(D12)) -> 7473.8084
A13: ='Cable Database'!A9 -> CV-FD 1C 35 | B13: ='Cable Database'!C9 -> 1 | C13: ='Cable Database'!D9 -> 35 | D13: ='Cable Database'!E9*(1+'Assumptions & Sources'!$B$4*($B$5-'Assumptions & Sources'!$B$8)) -> 0.6681524 | E13: ='Cable Database'!H9 -> 0.08 | F13: =400*$B$4*1000/(SQRT(3)*100*(D13*0.8+E13*SQRT(1-0.8^2))) -> 118.93464 | G13: =400*$B$4*1000/(SQRT(3)*100*(D13*0.95+E13*SQRT(1-0.95^2))) -> 105.01657 | H13: =400*$B$4*1000/(SQRT(3)*100*D13) -> 103.69196 | I13: =230*$B$4*1000/(2*50*(D13*0.95+E13*SQRT(1-0.95^2))) -> 104.58907 | J13: =1000*$B$4*1000/(2*100*D13) -> 224.49968 | K13: =400*$B$4*1000/(SQRT(3)*(D13)) -> 10369.196
A14: ='Cable Database'!A10 -> CV-FD 4C 35 | B14: ='Cable Database'!C10 -> 4 | C14: ='Cable Database'!D10 -> 35 | D14: ='Cable Database'!E10*(1+'Assumptions & Sources'!$B$4*($B$5-'Assumptions & Sources'!$B$8)) -> 0.6681524 | E14: ='Cable Database'!H10 -> 0.08 | F14: =400*$B$4*1000/(SQRT(3)*100*(D14*0.8+E14*SQRT(1-0.8^2))) -> 118.93464 | G14: =400*$B$4*1000/(SQRT(3)*100*(D14*0.95+E14*SQRT(1-0.95^2))) -> 105.01657 | H14: =400*$B$4*1000/(SQRT(3)*100*D14) -> 103.69196 | I14: =230*$B$4*1000/(2*50*(D14*0.95+E14*SQRT(1-0.95^2))) -> 104.58907 | J14: =1000*$B$4*1000/(2*100*D14) -> 224.49968 | K14: =400*$B$4*1000/(SQRT(3)*(D14)) -> 10369.196
A15: ='Cable Database'!A11 -> CV-FD 1C 50 | B15: ='Cable Database'!C11 -> 1 | C15: ='Cable Database'!D11 -> 50 | D15: ='Cable Database'!E11*(1+'Assumptions & Sources'!$B$4*($B$5-'Assumptions & Sources'!$B$8)) -> 0.4934637 | E15: ='Cable Database'!H11 -> 0.08 | F15: =400*$B$4*1000/(SQRT(3)*100*(D15*0.8+E15*SQRT(1-0.8^2))) -> 156.47375 | G15: =400*$B$4*1000/(SQRT(3)*100*(D15*0.95+E15*SQRT(1-0.95^2))) -> 140.31221 | H15: =400*$B$4*1000/(SQRT(3)*100*D15) -> 140.39945 | I15: =230*$B$4*1000/(2*50*(D15*0.95+E15*SQRT(1-0.95^2))) -> 139.74103 | J15: =1000*$B$4*1000/(2*100*D15) -> 303.97373 | K15: =400*$B$4*1000/(SQRT(3)*(D15)) -> 14039.945
A16: ='Cable Database'!A12 -> CV-FD 1C 70 | B16: ='Cable Database'!C12 -> 1 | C16: ='Cable Database'!D12 -> 70 | D16: ='Cable Database'!E12*(1+'Assumptions & Sources'!$B$4*($B$5-'Assumptions & Sources'!$B$8)) -> 0.3417268 | E16: ='Cable Database'!H12 -> 0.08 | F16: =400*$B$4*1000/(SQRT(3)*100*(D16*0.8+E16*SQRT(1-0.8^2))) -> 215.57571 | G16: =400*$B$4*1000/(SQRT(3)*100*(D16*0.95+E16*SQRT(1-0.95^2))) -> 198.16356 | H16: =400*$B$4*1000/(SQRT(3)*100*D16) -> 202.741 | I16: =230*$B$4*1000/(2*50*(D16*0.95+E16*SQRT(1-0.95^2))) -> 197.35688 | J16: =1000*$B$4*1000/(2*100*D16) -> 438.94714 | K16: =400*$B$4*1000/(SQRT(3)*(D16)) -> 20274.1
A17: ='Cable Database'!A13 -> CV-FD 4C 70 | B17: ='Cable Database'!C13 -> 4 | C17: ='Cable Database'!D13 -> 70 | D17: ='Cable Database'!E13*(1+'Assumptions & Sources'!$B$4*($B$5-'Assumptions & Sources'!$B$8)) -> 0.3417268 | E17: ='Cable Database'!H13 -> 0.08 | F17: =400*$B$4*1000/(SQRT(3)*100*(D17*0.8+E17*SQRT(1-0.8^2))) -> 215.57571 | G17: =400*$B$4*1000/(SQRT(3)*100*(D17*0.95+E17*SQRT(1-0.95^2))) -> 198.16356 | H17: =400*$B$4*1000/(SQRT(3)*100*D17) -> 202.741 | I17: =230*$B$4*1000/(2*50*(D17*0.95+E17*SQRT(1-0.95^2))) -> 197.35688 | J17: =1000*$B$4*1000/(2*100*D17) -> 438.94714 | K17: =400*$B$4*1000/(SQRT(3)*(D17)) -> 20274.1
A18: ='Cable Database'!A14 -> CV-FD 1C 95 | B18: ='Cable Database'!C14 -> 1 | C18: ='Cable Database'!D14 -> 95 | D18: ='Cable Database'!E14*(1+'Assumptions & Sources'!$B$4*($B$5-'Assumptions & Sources'!$B$8)) -> 0.2460943 | E18: ='Cable Database'!H14 -> 0.08 | F18: =400*$B$4*1000/(SQRT(3)*100*(D18*0.8+E18*SQRT(1-0.8^2))) -> 282.92765 | G18: =400*$B$4*1000/(SQRT(3)*100*(D18*0.95+E18*SQRT(1-0.95^2))) -> 267.73639 | H18: =400*$B$4*1000/(SQRT(3)*100*D18) -> 281.52636 | I18: =230*$B$4*1000/(2*50*(D18*0.95+E18*SQRT(1-0.95^2))) -> 266.64649 | J18: =1000*$B$4*1000/(2*100*D18) -> 609.52245 | K18: =400*$B$4*1000/(SQRT(3)*(D18)) -> 28152.636
A19: ='Cable Database'!A15 -> CV-FD 1C 120 | B19: ='Cable Database'!C15 -> 1 | C19: ='Cable Database'!D15 -> 120 | D19: ='Cable Database'!E15*(1+'Assumptions & Sources'!$B$4*($B$5-'Assumptions & Sources'!$B$8)) -> 0.1950903 | E19: ='Cable Database'!H15 -> 0.08 | F19: =400*$B$4*1000/(SQRT(3)*100*(D19*0.8+E19*SQRT(1-0.8^2))) -> 339.49758 | G19: =400*$B$4*1000/(SQRT(3)*100*(D19*0.95+E19*SQRT(1-0.95^2))) -> 329.41909 | H19: =400*$B$4*1000/(SQRT(3)*100*D19) -> 355.12802 | I19: =230*$B$4*1000/(2*50*(D19*0.95+E19*SQRT(1-0.95^2))) -> 328.0781 | J19: =1000*$B$4*1000/(2*100*D19) -> 768.87472 | K19: =400*$B$4*1000/(SQRT(3)*(D19)) -> 35512.802
... A22: ='Cable Database'!A18 -> CV-FD 1C 240 | B22: ='Cable Database'!C18 -> 1 | C22: ='Cable Database'!D18 -> 240 | D22: ='Cable Database'!E18*(1+'Assumptions & Sources'!$B$4*($B$5-'Assumptions & Sources'!$B$8)) -> 0.09614254 | E22: ='Cable Database'!H18 -> 0.08 | F22: =400*$B$4*1000/(SQRT(3)*100*(D22*0.8+E22*SQRT(1-0.8^2))) -> 554.63771 | G22: =400*$B$4*1000/(SQRT(3)*100*(D22*0.95+E22*SQRT(1-0.95^2))) -> 595.63935 | H22: =400*$B$4*1000/(SQRT(3)*100*D22) -> 720.61787 | I22: =230*$B$4*1000/(2*50*(D22*0.95+E22*SQRT(1-0.95^2))) -> 593.21463 | J22: =1000*$B$4*1000/(2*100*D22) -> 1560.1835 | K22: =400*$B$4*1000/(SQRT(3)*(D22)) -> 72061.787
A24: Tip: maximum length is inversely proportional to load current. Use the Calculator sheet for the exact project load, voltage, PF and route length.
A27: AC Sensitivity | Maximum one-way route length for adjustable current and PF | B27: AC Sensitivity | Maximum one-way route length for adjustable current and PF | C27: AC Sensitivity | Maximum one-way route length for adjustable current and PF | D27: AC Sensitivity | Maximum one-way route length for adjustable current and PF | E27: AC Sensitivity | Maximum one-way route length for adjustable current and PF | F27: AC Sensitivity | Maximum one-way route length for adjustable current and PF | G27: AC Sensitivity | Maximum one-way route length for adjustable current and PF | H27: AC Sensitivity | Maximum one-way route length for adjustable current and PF | I27: AC Sensitivity | Maximum one-way route length for adjustable current and PF | J27: AC Sensitivity | Maximum one-way route length for adjustable current and PF | K27: AC Sensitivity | Maximum one-way route length for adjustable current and PF
A28: Adjustable AC inputs | B28: Value | D28: 3Φ AC adjustable maximum route length | E28: 3Φ AC adjustable maximum route length | F28: 3Φ AC adjustable maximum route length | G28: 3Φ AC adjustable maximum route length | H28: 3Φ AC adjustable maximum route length | I28: 3Φ AC adjustable maximum route length | J28: 3Φ AC adjustable maximum route length | K28: 3Φ AC adjustable maximum route length
A29: System voltage (V) | B29: 400 | D29: Cable ID | E29: Cores | F29: Area (sq.mm.) | G29: R at temp (Ω/km) | H29: X (Ω/km) | I29: Max length (m) | J29: m per A | K29: Status / note
A30: Current (A) | B30: 100 | D30: =A8 -> CV-FD 4C 10 | E30: =B8 -> 4 | F30: =C8 -> 10 | G30: =D8 -> 2.333433 | H30: =E8 -> 0.08 | I30: =$B$29*$B$33*1000/(SQRT(3)*$B$30*(G30*$B$31+H30*SQRT(1-$B$31^2))) -> 30.905453 | J30: =I30/$B$30 -> 0.30905453 | K30: Formula-driven
A31: Power Factor (PF) | B31: 0.95 | D31: =A9 -> CV-FD 1C 16 | E31: =B9 -> 1 | F31: =C9 -> 16 | G31: =D9 -> 1.466365 | H31: =E9 -> 0.08 | I31: =$B$29*$B$33*1000/(SQRT(3)*$B$30*(G31*$B$31+H31*SQRT(1-$B$31^2))) -> 48.858058 | J31: =I31/$B$30 -> 0.48858058 | K31: Formula-driven
A32: Conductor temperature (°C) | B32: =$B$5 -> 90 | D32: =A10 -> CV-FD 4C 16 | E32: =B10 -> 4 | F32: =C10 -> 16 | G32: =D10 -> 1.466365 | H32: =E10 -> 0.08 | I32: =$B$29*$B$33*1000/(SQRT(3)*$B$30*(G32*$B$31+H32*SQRT(1-$B$31^2))) -> 48.858058 | J32: =I32/$B$30 -> 0.48858058 | K32: Formula-driven
A33: Voltage-drop limit | B33: =$B$4 -> 0.03 | D33: =A11 -> CV-FD 1C 25 | E33: =B11 -> 1 | F33: =C11 -> 25 | G33: =D11 -> 0.9269977 | H33: =E11 -> 0.08 | I33: =$B$29*$B$33*1000/(SQRT(3)*$B$30*(G33*$B$31+H33*SQRT(1-$B$31^2))) -> 76.501662 | J33: =I33/$B$30 -> 0.76501662 | K33: Formula-driven
D34: =A12 -> CV-FD 4C 25 | E34: =B12 -> 4 | F34: =C12 -> 25 | G34: =D12 -> 0.9269977 | H34: =E12 -> 0.08 | I34: =$B$29*$B$33*1000/(SQRT(3)*$B$30*(G34*$B$31+H34*SQRT(1-$B$31^2))) -> 76.501662 | J34: =I34/$B$30 -> 0.76501662 | K34: Formula-driven
A35: ปรับค่าเซลล์สีเหลือง: Voltage / Current / PF; ค่า Temp และ Vdrop สีเขียวเชื่อมจาก Common inputs | B35: ปรับค่าเซลล์สีเหลือง: Voltage / Current / PF; ค่า Temp และ Vdrop สีเขียวเชื่อมจาก Common inputs | D35: =A13 -> CV-FD 1C 35 | E35: =B13 -> 1 | F35: =C13 -> 35 | G35: =D13 -> 0.6681524 | H35: =E13 -> 0.08 | I35: =$B$29*$B$33*1000/(SQRT(3)*$B$30*(G35*$B$31+H35*SQRT(1-$B$31^2))) -> 105.01657 | J35: =I35/$B$30 -> 1.0501657 | K35: Formula-driven
D36: =A14 -> CV-FD 4C 35 | E36: =B14 -> 4 | F36: =C14 -> 35 | G36: =D14 -> 0.6681524 | H36: =E14 -> 0.08 | I36: =$B$29*$B$33*1000/(SQRT(3)*$B$30*(G36*$B$31+H36*SQRT(1-$B$31^2))) -> 105.01657 | J36: =I36/$B$30 -> 1.0501657 | K36: Formula-driven
D37: =A15 -> CV-FD 1C 50 | E37: =B15 -> 1 | F37: =C15 -> 50 | G37: =D15 -> 0.4934637 | H37: =E15 -> 0.08 | I37: =$B$29*$B$33*1000/(SQRT(3)*$B$30*(G37*$B$31+H37*SQRT(1-$B$31^2))) -> 140.31221 | J37: =I37/$B$30 -> 1.4031221 | K37: Formula-driven
D38: =A16 -> CV-FD 1C 70 | E38: =B16 -> 1 | F38: =C16 -> 70 | G38: =D16 -> 0.3417268 | H38: =E16 -> 0.08 | I38: =$B$29*$B$33*1000/(SQRT(3)*$B$30*(G38*$B$31+H38*SQRT(1-$B$31^2))) -> 198.16356 | J38: =I38/$B$30 -> 1.9816356 | K38: Formula-driven
D39: =A17 -> CV-FD 4C 70 | E39: =B17 -> 4 | F39: =C17 -> 70 | G39: =D17 -> 0.3417268 | H39: =E17 -> 0.08 | I39: =$B$29*$B$33*1000/(SQRT(3)*$B$30*(G39*$B$31+H39*SQRT(1-$B$31^2))) -> 198.16356 | J39: =I39/$B$30 -> 1.9816356 | K39: Formula-driven
D40: =A18 -> CV-FD 1C 95 | E40: =B18 -> 1 | F40: =C18 -> 95 | G40: =D18 -> 0.2460943 | H40: =E18 -> 0.08 | I40: =$B$29*$B$33*1000/(SQRT(3)*$B$30*(G40*$B$31+H40*SQRT(1-$B$31^2))) -> 267.73639 | J40: =I40/$B$30 -> 2.6773639 | K40: Formula-driven
D41: =A19 -> CV-FD 1C 120 | E41: =B19 -> 1 | F41: =C19 -> 120 | G41: =D19 -> 0.1950903 | H41: =E19 -> 0.08 | I41: =$B$29*$B$33*1000/(SQRT(3)*$B$30*(G41*$B$31+H41*SQRT(1-$B$31^2))) -> 329.41909 | J41: =I41/$B$30 -> 3.2941909 | K41: Formula-driven
D42: =A20 -> CV-FD 1C 150 | E42: =B20 -> 1 | F42: =C20 -> 150 | G42: =D20 -> 0.1581124 | H42: =E20 -> 0.08 | I42: =$B$29*$B$33*1000/(SQRT(3)*$B$30*(G42*$B$31+H42*SQRT(1-$B$31^2))) -> 395.47525 | J42: =I42/$B$30 -> 3.9547525 | K42: Formula-driven
D43: =A21 -> CV-FD 1C 185 | E43: =B21 -> 1 | F43: =C21 -> 185 | G43: =D21 -> 0.12636241 | H43: =E21 -> 0.08 | I43: =$B$29*$B$33*1000/(SQRT(3)*$B$30*(G43*$B$31+H43*SQRT(1-$B$31^2))) -> 477.72712 | J43: =I43/$B$30 -> 4.7772712 | K43: Formula-driven
D44: =A22 -> CV-FD 1C 240 | E44: =B22 -> 1 | F44: =C22 -> 240 | G44: =D22 -> 0.09614254 | H44: =E22 -> 0.08 | I44: =$B$29*$B$33*1000/(SQRT(3)*$B$30*(G44*$B$31+H44*SQRT(1-$B$31^2))) -> 595.63935 | J44: =I44/$B$30 -> 5.9563935 | K44: Formula-driven
A47: AC Standard Method | EIT/WST Table 4.4 | XLPE cable voltage drop at 90°C | B47: AC Standard Method | EIT/WST Table 4.4 | XLPE cable voltage drop at 90°C | C47: AC Standard Method | EIT/WST Table 4.4 | XLPE cable voltage drop at 90°C | D47: AC Standard Method | EIT/WST Table 4.4 | XLPE cable voltage drop at 90°C | E47: AC Standard Method | EIT/WST Table 4.4 | XLPE cable voltage drop at 90°C | F47: AC Standard Method | EIT/WST Table 4.4 | XLPE cable voltage drop at 90°C | G47: AC Standard Method | EIT/WST Table 4.4 | XLPE cable voltage drop at 90°C | H47: AC Standard Method | EIT/WST Table 4.4 | XLPE cable voltage drop at 90°C | I47: AC Standard Method | EIT/WST Table 4.4 | XLPE cable voltage drop at 90°C | J47: AC Standard Method | EIT/WST Table 4.4 | XLPE cable voltage drop at 90°C | K47: AC Standard Method | EIT/WST Table 4.4 | XLPE cable voltage drop at 90°C | L47: AC Standard Method | EIT/WST Table 4.4 | XLPE cable voltage drop at 90°C | M47: AC Standard Method | EIT/WST Table 4.4 | XLPE cable voltage drop at 90°C | N47: AC Standard Method | EIT/WST Table 4.4 | XLPE cable voltage drop at 90°C
A48: Calculation inputs | B48: Value | D48: Voltage drop calculation from standard mV/A/m values | K48: ใช้ PF | L48: ใช้ PF | M48: L max @ (A) | N48: =B51 -> 100
...

Sheet DC Calculator
A1: DC PV String Voltage-Drop Calculator | Jinko 725 Wp | Phelps Dodge / Bangkok Cable | B1: DC PV String Voltage-Drop Calculator | Jinko 725 Wp | Phelps Dodge / Bangkok Cable | C1: DC PV String Voltage-Drop Calculator | Jinko 725 Wp | Phelps Dodge / Bangkok Cable | D1: DC PV String Voltage-Drop Calculator | Jinko 725 Wp | Phelps Dodge / Bangkok Cable | E1: DC PV String Voltage-Drop Calculator | Jinko 725 Wp | Phelps Dodge / Bangkok Cable | F1: DC PV String Voltage-Drop Calculator | Jinko 725 Wp | Phelps Dodge / Bangkok Cable | G1: DC PV String Voltage-Drop Calculator | Jinko 725 Wp | Phelps Dodge / Bangkok Cable | H1: DC PV String Voltage-Drop Calculator | Jinko 725 Wp | Phelps Dodge / Bangkok Cable
A3: Enter or select yellow cells. All lengths are one-way route lengths. The DC formula includes the positive and negative conductors. | B3: Enter or select yellow cells. All lengths are one-way route lengths. The DC formula includes the positive and negative conductors. | C3: Enter or select yellow cells. All lengths are one-way route lengths. The DC formula includes the positive and negative conductors. | D3: Enter or select yellow cells. All lengths are one-way route lengths. The DC formula includes the positive and negative conductors. | E3: Enter or select yellow cells. All lengths are one-way route lengths. The DC formula includes the positive and negative conductors. | F3: Enter or select yellow cells. All lengths are one-way route lengths. The DC formula includes the positive and negative conductors. | G3: Enter or select yellow cells. All lengths are one-way route lengths. The DC formula includes the positive and negative conductors. | H3: Enter or select yellow cells. All lengths are one-way route lengths. The DC formula includes the positive and negative conductors.
A5: INPUT | B5: VALUE | D5: CALCULATED RESULT | E5: VALUE
A6: Cable ID | B6: Bangkok Cable H1Z2Z2-K 6 mm² | D6: Rdc @20°C (Ω/km) | E6: =VLOOKUP($B$6,'DC Cable Database'!$A$4:$O$32,5,FALSE) -> 3.39
A7: Modules in series (modules/string) | B7: 20 | D7: Vmp/module (V) | E7: ='Panel Datasheet'!$B$6 -> 41
A8: One-way route length (m) | B8: 100 | D8: Imp/module (A) | E8: ='Panel Datasheet'!$B$7 -> 17.69
A9: Voltage-drop limit | B9: 0.03 | D9: Voc/module STC (V) | E9: ='Panel Datasheet'!$B$8 -> 49.2
A10: Operating conductor temperature (°C) | B10: 90 | D10: String Vmp (V) | E10: =$B$7*E7 -> 820
A11: Design minimum cell temperature (°C) | B11: 10 | D11: String Imp (A) | E11: =E8 -> 17.69
A12: Inverter maximum DC input voltage (V) | B12: 1100 | D12: String Pmp at Vmp×Imp (W) | E12: =E10*E11 -> 14505.8
A13: Notes / circuit name | B13: Example: 20-module string to inverter | D13: Voc/module at min cell temp (V) | E13: =E9*(1+'Panel Datasheet'!$B$14*($B$11-25)) -> 51.045
A14: Cable selection basis | B14: Voltage Drop + ampacity check only | D14: String Voc at min cell temp (V) | E14: =$B$7*E13 -> 1020.9
D15: Rdc @ operating temp (Ω/km) | E15: =E6*(1+'Assumptions & Sources'!$B$20*($B$10-'Assumptions & Sources'!$B$8)) -> 4.322589
D16: Loop resistance (Ω) | E16: =2*E15*$B$8/1000 -> 0.8645178
D17: Voltage drop ΔV (V) | E17: =E11*E16 -> 15.29332
D18: Voltage drop (%) | E18: =E17/E10 -> 0.01865039
B19: ขั้นตอนการเลือกสาย DC ยังไม่ได้รวมในนี้ | D19: Power loss (W) | E19: =E11^2*E16 -> 270.53883
B20: 1) ชนิดสาย | D20: Power loss (%) | E20: =E19/E12 -> 0.01865039
B21: 2) กลุ่มการติดตั้ง | D21: Maximum one-way route length (m) | E21: =E10*$B$9*1000/(2*E15*E11) -> 160.85454
B22: 3) Factor จำนวนสายไฟ | D22: Margin to limit (m) | E22: =E21-$B$8 -> 60.854544
B23: 4) Factor อุณหภูมิสภาพแวดล้อม | D23: Ampacity: two loaded / surface (A) | E23: =VLOOKUP($B$6,'DC Cable Database'!$A$4:$O$32,9,FALSE) -> 57 | F23: ดู K Factor - กลุ่มการติดตั้ง /หรือดูค่า A จากตาราง วสท.
B24: 5) ใช้ R จากผู้ผลิตคำนวณ Voltage Drop | D24: Ampacity status | E24: =IF(E23>=E11,"PASS","CHECK") -> PASS
D25: Cable rated voltage (V DC) | E25: =VLOOKUP($B$6,'DC Cable Database'!$A$4:$O$32,10,FALSE)*1000 -> 1500
D26: Voltage rating status | E26: =IF(E14<=E25,"PASS","CHECK") -> PASS
D27: Cable max conductor temp (°C) | E27: =VLOOKUP($B$6,'DC Cable Database'!$A$4:$O$32,11,FALSE) -> 120
D28: Temperature input status | E28: =IF($B$10<=E27,"PASS","CHECK") -> PASS
D29: Overall result | E29: =IF(AND(E18<=$B$9,E24="PASS",E26="PASS",E28="PASS"),"PASS","CHECK") -> PASS
D31: Formula: ΔV = 2 × I × L × Rθ / 1000, where Rθ is in Ω/km and L is one-way in m. Power loss = I² × loop resistance. | E31: Formula: ΔV = 2 × I × L × Rθ / 1000, where Rθ is in Ω/km and L is one-way in m. Power loss = I² × loop resistance. | F31: Formula: ΔV = 2 × I × L × Rθ / 1000, where Rθ is in Ω/km and L is one-way in m. Power loss = I² × loop resistance. | G31: Formula: ΔV = 2 × I × L × Rθ / 1000, where Rθ is in Ω/km and L is one-way in m. Power loss = I² × loop resistance. | H31: Formula: ΔV = 2 × I × L × Rθ / 1000, where Rθ is in Ω/km and L is one-way in m. Power loss = I² × loop resistance.
A33: Important: this is a Voltage Drop and preliminary ampacity check. Verify installation method, grouping/temperature derating, connectors, protection, short-circuit duty, earthing and inverter limits separately. | B33: Important: this is a Voltage Drop and preliminary ampacity check. Verify installation method, grouping/temperature derating, connectors, protection, short-circuit duty, earthing and inverter limits separately. | C33: Important: this is a Voltage Drop and preliminary ampacity check. Verify installation method, grouping/temperature derating, connectors, protection, short-circuit duty, earthing and inverter limits separately. | D33: Important: this is a Voltage Drop and preliminary ampacity check. Verify installation method, grouping/temperature derating, connectors, protection, short-circuit duty, earthing and inverter limits separately. | E33: Important: this is a Voltage Drop and preliminary ampacity check. Verify installation method, grouping/temperature derating, connectors, protection, short-circuit duty, earthing and inverter limits separately. | F33: Important: this is a Voltage Drop and preliminary ampacity check. Verify installation method, grouping/temperature derating, connectors, protection, short-circuit duty, earthing and inverter limits separately. | G33: Important: this is a Voltage Drop and preliminary ampacity check. Verify installation method, grouping/temperature derating, connectors, protection, short-circuit duty, earthing and inverter limits separately. | H33: Important: this is a Voltage Drop and preliminary ampacity check. Verify installation method, grouping/temperature derating, connectors, protection, short-circuit duty, earthing and inverter limits separately.

Sheet DC Quick Reference
A1: DC Quick Reference | Maximum one-way route length for Voltage Drop target | B1: DC Quick Reference | Maximum one-way route length for Voltage Drop target | C1: DC Quick Reference | Maximum one-way route length for Voltage Drop target | D1: DC Quick Reference | Maximum one-way route length for Voltage Drop target | E1: DC Quick Reference | Maximum one-way route length for Voltage Drop target | F1: DC Quick Reference | Maximum one-way route length for Voltage Drop target | G1: DC Quick Reference | Maximum one-way route length for Voltage Drop target | H1: DC Quick Reference | Maximum one-way route length for Voltage Drop target | I1: DC Quick Reference | Maximum one-way route length for Voltage Drop target | J1: DC Quick Reference | Maximum one-way route length for Voltage Drop target | K1: DC Quick Reference | Maximum one-way route length for Voltage Drop target
A3: Common inputs | B3: Value | D3: Reference settings | E3: Value
A4: Selected Pmax (Wp) | B4: ='Panel Datasheet'!$B$5 -> 725 | D4: Operating conductor temperature (°C) | E4: 90
A5: Vmp/module (V) | B5: ='Panel Datasheet'!$B$6 -> 41 | D5: Minimum cell temperature (°C) | E5: 10
A6: Imp/module (A) | B6: ='Panel Datasheet'!$B$7 -> 17.69 | D6: Length basis | E6: One-way route length
A7: Voltage-drop target | B7: 0.03 | D7: Cable sizes highlighted | E7: 4 / 6 / 10 mm²
D8: Method | E8: 2-wire DC; positive + negative
A10: Common sizes | Maximum one-way length at 10-module, 15-module and 20-module strings | B10: Common sizes | Maximum one-way length at 10-module, 15-module and 20-module strings | C10: Common sizes | Maximum one-way length at 10-module, 15-module and 20-module strings | D10: Common sizes | Maximum one-way length at 10-module, 15-module and 20-module strings | E10: Common sizes | Maximum one-way length at 10-module, 15-module and 20-module strings | F10: Common sizes | Maximum one-way length at 10-module, 15-module and 20-module strings | G10: Common sizes | Maximum one-way length at 10-module, 15-module and 20-module strings | H10: Common sizes | Maximum one-way length at 10-module, 15-module and 20-module strings | I10: Common sizes | Maximum one-way length at 10-module, 15-module and 20-module strings | J10: Common sizes | Maximum one-way length at 10-module, 15-module and 20-module strings | K10: Common sizes | Maximum one-way length at 10-module, 15-module and 20-module strings
F11: 10 modules (m) | G11: 10 modules (m) | H11: 10 modules (m) | I11: 10 modules (m) | J11: 15 modules (m) | K11: 20 modules (m)
A12: Cable ID | B12: Manufacturer | C12: Area (mm²) | D12: Rdc @90°C (Ω/km) | E12: Ampacity two loaded / surface (A) | F12: 0.01 | G12: 0.015 | H12: 0.02 | I12: 0.03 | J12: =B7 -> 0.03 | K12: =B7 -> 0.03
A13: Phelps Dodge H1Z2Z2-K 4 mm² | B13: =VLOOKUP($A13,'DC Cable Database'!$A$4:$O$32,2,FALSE) -> Phelps Dodge | C13: =VLOOKUP($A13,'DC Cable Database'!$A$4:$O$32,4,FALSE) -> 4 | D13: =VLOOKUP($A13,'DC Cable Database'!$A$4:$O$32,13,FALSE) -> 6.490259 | E13: =VLOOKUP($A13,'DC Cable Database'!$A$4:$O$32,9,FALSE) -> 44 | F13: ='Panel Datasheet'!$B$6*10*F$12*1000/(2*$D13*'Panel Datasheet'!$B$7) -> 17.85517 | G13: ='Panel Datasheet'!$B$6*10*G$12*1000/(2*$D13*'Panel Datasheet'!$B$7) -> 26.782756 | H13: ='Panel Datasheet'!$B$6*10*H$12*1000/(2*$D13*'Panel Datasheet'!$B$7) -> 35.710341 | I13: ='Panel Datasheet'!$B$6*10*I$12*1000/(2*$D13*'Panel Datasheet'!$B$7) -> 53.565511 | J13: ='Panel Datasheet'!$B$6*15*$B$7*1000/(2*$D13*'Panel Datasheet'!$B$7) -> 80.348267 | K13: ='Panel Datasheet'!$B$6*20*$B$7*1000/(2*$D13*'Panel Datasheet'!$B$7) -> 107.13102
A14: Phelps Dodge H1Z2Z2-K 6 mm² | B14: =VLOOKUP($A14,'DC Cable Database'!$A$4:$O$32,2,FALSE) -> Phelps Dodge | C14: =VLOOKUP($A14,'DC Cable Database'!$A$4:$O$32,4,FALSE) -> 6 | D14: =VLOOKUP($A14,'DC Cable Database'!$A$4:$O$32,13,FALSE) -> 4.322589 | E14: =VLOOKUP($A14,'DC Cable Database'!$A$4:$O$32,9,FALSE) -> 57 | F14: ='Panel Datasheet'!$B$6*10*F$12*1000/(2*$D14*'Panel Datasheet'!$B$7) -> 26.809091 | G14: ='Panel Datasheet'!$B$6*10*G$12*1000/(2*$D14*'Panel Datasheet'!$B$7) -> 40.213636 | H14: ='Panel Datasheet'!$B$6*10*H$12*1000/(2*$D14*'Panel Datasheet'!$B$7) -> 53.618181 | I14: ='Panel Datasheet'!$B$6*10*I$12*1000/(2*$D14*'Panel Datasheet'!$B$7) -> 80.427272 | J14: ='Panel Datasheet'!$B$6*15*$B$7*1000/(2*$D14*'Panel Datasheet'!$B$7) -> 120.64091 | K14: ='Panel Datasheet'!$B$6*20*$B$7*1000/(2*$D14*'Panel Datasheet'!$B$7) -> 160.85454
A15: Phelps Dodge H1Z2Z2-K 10 mm² | B15: =VLOOKUP($A15,'DC Cable Database'!$A$4:$O$32,2,FALSE) -> Phelps Dodge | C15: =VLOOKUP($A15,'DC Cable Database'!$A$4:$O$32,4,FALSE) -> 10 | D15: =VLOOKUP($A15,'DC Cable Database'!$A$4:$O$32,13,FALSE) -> 2.486445 | E15: =VLOOKUP($A15,'DC Cable Database'!$A$4:$O$32,9,FALSE) -> 79 | F15: ='Panel Datasheet'!$B$6*10*F$12*1000/(2*$D15*'Panel Datasheet'!$B$7) -> 46.606573 | G15: ='Panel Datasheet'!$B$6*10*G$12*1000/(2*$D15*'Panel Datasheet'!$B$7) -> 69.90986 | H15: ='Panel Datasheet'!$B$6*10*H$12*1000/(2*$D15*'Panel Datasheet'!$B$7) -> 93.213146 | I15: ='Panel Datasheet'!$B$6*10*I$12*1000/(2*$D15*'Panel Datasheet'!$B$7) -> 139.81972 | J15: ='Panel Datasheet'!$B$6*15*$B$7*1000/(2*$D15*'Panel Datasheet'!$B$7) -> 209.72958 | K15: ='Panel Datasheet'!$B$6*20*$B$7*1000/(2*$D15*'Panel Datasheet'!$B$7) -> 279.63944
A16: Bangkok Cable H1Z2Z2-K 4 mm² | B16: =VLOOKUP($A16,'DC Cable Database'!$A$4:$O$32,2,FALSE) -> Bangkok Cable | C16: =VLOOKUP($A16,'DC Cable Database'!$A$4:$O$32,4,FALSE) -> 4 | D16: =VLOOKUP($A16,'DC Cable Database'!$A$4:$O$32,13,FALSE) -> 6.490259 | E16: =VLOOKUP($A16,'DC Cable Database'!$A$4:$O$32,9,FALSE) -> 44 | F16: ='Panel Datasheet'!$B$6*10*F$12*1000/(2*$D16*'Panel Datasheet'!$B$7) -> 17.85517 | G16: ='Panel Datasheet'!$B$6*10*G$12*1000/(2*$D16*'Panel Datasheet'!$B$7) -> 26.782756 | H16: ='Panel Datasheet'!$B$6*10*H$12*1000/(2*$D16*'Panel Datasheet'!$B$7) -> 35.710341 | I16: ='Panel Datasheet'!$B$6*10*I$12*1000/(2*$D16*'Panel Datasheet'!$B$7) -> 53.565511 | J16: ='Panel Datasheet'!$B$6*15*$B$7*1000/(2*$D16*'Panel Datasheet'!$B$7) -> 80.348267 | K16: ='Panel Datasheet'!$B$6*20*$B$7*1000/(2*$D16*'Panel Datasheet'!$B$7) -> 107.13102
A17: Bangkok Cable H1Z2Z2-K 6 mm² | B17: =VLOOKUP($A17,'DC Cable Database'!$A$4:$O$32,2,FALSE) -> Bangkok Cable | C17: =VLOOKUP($A17,'DC Cable Database'!$A$4:$O$32,4,FALSE) -> 6 | D17: =VLOOKUP($A17,'DC Cable Database'!$A$4:$O$32,13,FALSE) -> 4.322589 | E17: =VLOOKUP($A17,'DC Cable Database'!$A$4:$O$32,9,FALSE) -> 57 | F17: ='Panel Datasheet'!$B$6*10*F$12*1000/(2*$D17*'Panel Datasheet'!$B$7) -> 26.809091 | G17: ='Panel Datasheet'!$B$6*10*G$12*1000/(2*$D17*'Panel Datasheet'!$B$7) -> 40.213636 | H17: ='Panel Datasheet'!$B$6*10*H$12*1000/(2*$D17*'Panel Datasheet'!$B$7) -> 53.618181 | I17: ='Panel Datasheet'!$B$6*10*I$12*1000/(2*$D17*'Panel Datasheet'!$B$7) -> 80.427272 | J17: ='Panel Datasheet'!$B$6*15*$B$7*1000/(2*$D17*'Panel Datasheet'!$B$7) -> 120.64091 | K17: ='Panel Datasheet'!$B$6*20*$B$7*1000/(2*$D17*'Panel Datasheet'!$B$7) -> 160.85454
A18: Bangkok Cable H1Z2Z2-K 10 mm² | B18: =VLOOKUP($A18,'DC Cable Database'!$A$4:$O$32,2,FALSE) -> Bangkok Cable | C18: =VLOOKUP($A18,'DC Cable Database'!$A$4:$O$32,4,FALSE) -> 10 | D18: =VLOOKUP($A18,'DC Cable Database'!$A$4:$O$32,13,FALSE) -> 2.486445 | E18: =VLOOKUP($A18,'DC Cable Database'!$A$4:$O$32,9,FALSE) -> 79 | F18: ='Panel Datasheet'!$B$6*10*F$12*1000/(2*$D18*'Panel Datasheet'!$B$7) -> 46.606573 | G18: ='Panel Datasheet'!$B$6*10*G$12*1000/(2*$D18*'Panel Datasheet'!$B$7) -> 69.90986 | H18: ='Panel Datasheet'!$B$6*10*H$12*1000/(2*$D18*'Panel Datasheet'!$B$7) -> 93.213146 | I18: ='Panel Datasheet'!$B$6*10*I$12*1000/(2*$D18*'Panel Datasheet'!$B$7) -> 139.81972 | J18: ='Panel Datasheet'!$B$6*15*$B$7*1000/(2*$D18*'Panel Datasheet'!$B$7) -> 209.72958 | K18: ='Panel Datasheet'!$B$6*20*$B$7*1000/(2*$D18*'Panel Datasheet'!$B$7) -> 279.63944
A21: All cable sizes in source datasheets | Target = 3.0% | Use this table to compare manufacturers and larger sizes | B21: All cable sizes in source datasheets | Target = 1.5% | Use this table to compare manufacturers and larger sizes | C21: All cable sizes in source datasheets | Target = 1.5% | Use this table to compare manufacturers and larger sizes | D21: All cable sizes in source datasheets | Target = 1.5% | Use this table to compare manufacturers and larger sizes | E21: All cable sizes in source datasheets | Target = 1.5% | Use this table to compare manufacturers and larger sizes | F21: All cable sizes in source datasheets | Target = 1.5% | Use this table to compare manufacturers and larger sizes | G21: All cable sizes in source datasheets | Target = 1.5% | Use this table to compare manufacturers and larger sizes | H21: All cable sizes in source datasheets | Target = 1.5% | Use this table to compare manufacturers and larger sizes | I21: All cable sizes in source datasheets | Target = 1.5% | Use this table to compare manufacturers and larger sizes | J21: All cable sizes in source datasheets | Target = 1.5% | Use this table to compare manufacturers and larger sizes | K21: All cable sizes in source datasheets | Target = 1.5% | Use this table to compare manufacturers and larger sizes
