Workbook

Sheet Read Me
A1: Cable Containment Data Register — Expert Update 2026-08-01 / Rev.4 | B1: Cable Containment Data Register - Example Inputs | C1: Cable Containment Data Register - Example Inputs | D1: Cable Containment Data Register - Example Inputs | E1: Cable Containment Data Register - Example Inputs | F1: Cable Containment Data Register - Example Inputs | G1: Cable Containment Data Register - Example Inputs | H1: Cable Containment Data Register - Example Inputs
A3: Field | B3: Value / instruction
A4: Status | B4: PRELIMINARY / EXAMPLE INPUTS - NOT APPROVED FOR CONSTRUCTION
A5: Conduit selected | B5: Panasonic White Conduit - IMC (ANSI/UL)
A6: Cable ladder selected | B6: KJL KLSG - Hot-Dip Galvanized Cable Ladder
A7: Purpose | B7: Formula-driven EIT physical-capacity screening for Panasonic IMC, cable ladder, cable tray and wireway. Rev.3 adds three input examples, Jinko 725 Wp reference, PV cable sizes 4/6/10/16 mm² and an editable Vendor Register OD master linked to all PV containment views.
A8: Conduit warning | B8: The catalogue gives nominal OD and minimum wall thickness, not a certified actual internal diameter. ID_screening is a formula for screening only.
A9: Ladder warning | B9: Nominal W x H is not automatically usable cable width/depth. Confirm shop drawing/profile and support arrangement before fill calculation.
A10: Engineering hold point | B10: Physical maximum is not an ampacity approval. Confirm actual IMC ID, usable ladder width, exact cable OD, circuit grouping, ambient factors, bending/pulling, support loads, earthing and corrosion class.
A11: Rev.4 central link | B11: Fill Calculator dropdowns use IMC Max Count!B10:B13; the OD returned from IMC Max Count!E10:E13 is linked to Vendor Register Phelps Dodge OD inputs.
A12: IMC selection | B12: IMC Max Count uses total Qty entered in the cable mix for 53% / 31% / 40% screening and provides single- or parallel-conduit recommendations.
A13: Area-only calculators | B13: Fill Calculator and Wireway Calculator use physical area fill only; no 0.8W condition is applied in either calculator.
A14: Separate width screen | B14: PV Wireway and PV Ladder/Cable Tray retain the requested additional ΣD_cable ≤ 0.8W screen where applicable.
A15: Use restriction | B15: Confirm exact cable OD, actual certified IMC internal diameter, ampacity, derating, support and bonding before IFC.

Sheet EIT Rules
A1: EIT / วสท. – Cable Containment Decision Rules | B1: EIT / วสท. – Cable Containment Decision Rules | C1: EIT / วสท. – Cable Containment Decision Rules | D1: EIT / วสท. – Cable Containment Decision Rules | E1: EIT / วสท. – Cable Containment Decision Rules | F1: EIT / วสท. – Cable Containment Decision Rules | G1: EIT / วสท. – Cable Containment Decision Rules
A3: ID | B3: ระบบ | C3: หลักเกณฑ์ใช้งาน | D3: ค่าหลัก | E3: ผลต่อ PV 1C / FD-CV | F3: แหล่งอ้างอิง | G3: สถานะ
A4: EIT-WW-01 | B4: Wireway | C4: ช่วงปกติ ห้ามพื้นที่หน้าตัดรวมของสายรวมฉนวนเกินพื้นที่ภายในราง | D4: 20% | E4: คำนวณจากพื้นที่หน้าตัดภายนอกจริงของสายทุกเส้น | F4: วสท. 022001-22 ข้อ 5.12; Bangkok Cable Guide PDF p.383-384 | G4: DESIGN RULE
A5: EIT-WW-02 | B5: Wireway | C5: จุดต่อ/แยกที่เปิดตรวจได้ พื้นที่รวมสายและ connector | D5: ไม่เกิน 75% | E5: ใช้เฉพาะบริเวณจุดต่อ; ต้องรวม connector และตรวจการเข้าถึง | F5: วสท. 022001-22 ข้อ 5.12 | G5: DESIGN RULE
A6: EIT-WW-03 | B6: Wireway | C6: เมื่อมีตัวนำกระแสเกิน 30 เส้น ต้องตรวจ ampacity/grouping เพิ่ม | D6: >30 CCC = derating check | E6: นับตัวนำที่มีกระแส ไม่ใช่นับจำนวน jacket; PE ไม่นับ และ neutral พิจารณาตามโหลด/ฮาร์มอนิก | F6: Bangkok Cable Guide PDF p.383; วสท. 022001-22 | G6: HOLD POINT
A7: EIT-WW-04 | B7: Wireway | C7: ตัวนำวงจรเดียวกัน รวมถึง PE ต้องจัดกลุ่ม/เดินร่วมกัน | D7: ทุกวงจร | E7: PV +/− ต้องเดินคู่ชิดกัน; AC phase/neutral/PE ต้องจัดกลุ่ม | F7: วสท. 022001-22 ข้อ 5.12 | G7: DESIGN RULE
A8: EIT-SEP-01 | B8: AC/DC | C8: แม้ฉนวนที่เหมาะสมอาจอนุญาตให้อยู่ใน enclosure เดียวกันได้ แนวทางโครงการให้แยก AC/DC | D8: Separate หรือ solid divider | E8: ลดความเสี่ยงสับสน, EMC, maintenance และเหตุฉุกเฉิน | F8: Bangkok Cable Guide PDF p.352; project engineering rule | G8: PROJECT RULE
A9: EIT-TR-01 | B9: Cable ladder/tray | C9: Cable tray/ladder ไม่มีเกณฑ์ fill 20% แบบ wireway; ต้องใช้ชนิดสายและตารางความกว้าง/พื้นที่ตามข้อ 5.15 | D9: No universal fill % | E9: ห้ามใช้สูตร 20% ตัดสิน ladder | F9: วสท. 022001-22 ข้อ 5.15 และตาราง 5-7 | G9: DESIGN RULE
A10: EIT-TR-02 | B10: Cable ladder/tray | C10: สายแกนเดียวมีเปลือก วางตรงบนรางได้เมื่อขนาดตัวนำไม่น้อยกว่า 25 mm²; สายหลายแกนวางได้ทุกขนาดตามเงื่อนไข | D10: 1C ≥25 mm² | E10: PV H1Z2Z2-K 4/6/10 mm² ไม่วางเปิดตรงบน ladder ภายใต้เกณฑ์ทั่วไป; FD-CV 1C ≥25 mm² จึงพิจารณาได้ | F10: Bangkok Cable Guide PDF p.241; วสท. 022001-22 ข้อ 5.15 | G10: CRITICAL
A11: EIT-TR-03 | B11: Cable ladder/tray | C11: สายไม่มีเปลือก เช่น IEC 01/THW ห้ามวางตรงบน tray/ladder | D11: Not permitted direct | E11: ต้องอยู่ในท่อ/ช่องเดินสายที่เหมาะสม | F11: Bangkok Cable Guide PDF p.240-241 | G11: CRITICAL
A12: EIT-TR-04 | B12: Cable ladder/tray | C12: จัดสายชั้นเดียวหรือ trefoil ตามชนิดวงจร ไม่ซ้อนหลายชั้น; มัดสาย 1C ของวงจรเดียวกันเป็นกลุ่ม | D12: Single layer / trefoil | E12: FD-CV 1C วงจร 3 เฟสต้องจัดกลุ่มและรักษาสมมาตร โดยเฉพาะวงจรขนาน | F12: Bangkok Cable Guide PDF p.241; วสท. 022001-22 | G12: DESIGN RULE
A13: EIT-TR-05 | B13: Cable ladder/tray | C13: ช่องเปิดไม่น้อยกว่า 30% เป็นนิยามรางระบายอากาศ ไม่ใช่เปอร์เซ็นต์บรรจุสาย | D13: 30% open area ≠ cable fill | E13: อย่านำ 30% ไปคูณพื้นที่รางเพื่อหาจำนวนสาย | F13: Bangkok Cable Guide PDF p.213 | G13: CLARIFICATION
A14: PV-STD-01 | B14: PV/BESS | C14: ตรวจฉบับ วสท. PV/BESS ปัจจุบันและข้อกำหนดการไฟฟ้าก่อนออกแบบรายละเอียด | D14: วสท. 022013-23 พ.ศ.2568 | E14: ข้อ 5.15 เป็นฐานทั่วไป; วิธีติดตั้ง PV ต้องยืนยันกับมาตรฐานเฉพาะและวิศวกร | F14: EIT official book page | G14: HOLD POINT

Sheet Conduit Data
A1: Panasonic IMC - Manufacturer Catalogue Data | B1: Panasonic IMC - Manufacturer Catalogue Data | C1: Panasonic IMC - Manufacturer Catalogue Data | D1: Panasonic IMC - Manufacturer Catalogue Data | E1: Panasonic IMC - Manufacturer Catalogue Data | F1: Panasonic IMC - Manufacturer Catalogue Data | G1: Panasonic IMC - Manufacturer Catalogue Data | H1: Panasonic IMC - Manufacturer Catalogue Data | I1: Panasonic IMC - Manufacturer Catalogue Data | J1: Panasonic IMC - Manufacturer Catalogue Data | K1: Panasonic IMC - Manufacturer Catalogue Data | L1: Panasonic IMC - Manufacturer Catalogue Data | M1: Panasonic IMC - Manufacturer Catalogue Data | N1: Panasonic IMC - Manufacturer Catalogue Data | O1: Panasonic IMC - Manufacturer Catalogue Data | P1: Panasonic IMC - Manufacturer Catalogue Data | Q1: Panasonic IMC - Manufacturer Catalogue Data
A3: Brand | B3: Series / type | C3: Item No. | D3: Trade size (inch) | E3: Outside diameter (mm) | F3: Minimum wall thickness (mm) | G3: Length (mm) | H3: Nominal weight (kg/pc) | I3: Primary bundle (pcs) | J3: Master bundle (pcs) | K3: ID_screening (mm) | L3: Area_screening (mm2) | M3: Confirmed actual ID (mm) | N3: Confirmed internal area (mm2) | O3: Standard / listing | P3: Source page | Q3: Status / remark
A4: Panasonic | B4: White Conduit IMC | C4: DWM012Y | D4: 1/2 | E4: 20.7 | F4: 1.79 | G4: 3030 | H4: 2.85 | I4: 10 | J4: 300 | K4: =E4-2*F4 -> 17.12 | L4: =PI()*K4^2/4 -> 230.1958 | M4: 17.12 | N4: =IF(M4="","",PI()*M4^2/4) -> 230.1958 | O4: UL 1242; catalogue also shows TIS 770 coverage | P4: PDF page 5 (printed pp. 7-8) | Q4: OPEN - confirm current product/certificate and actual ID
A5: Panasonic | B5: White Conduit IMC | C5: DWM034Y | D5: 3/4 | E5: 26.14 | F5: 1.9 | G5: 3030 | H5: 3.94 | I5: 5 | J5: 250 | K5: =E5-2*F5 -> 22.34 | L5: =PI()*K5^2/4 -> 391.97306 | M5: 22.34 | N5: =IF(M5="","",PI()*M5^2/4) -> 391.97306 | O5: UL 1242; catalogue also shows TIS 770 coverage | P5: PDF page 5 (printed pp. 7-8) | Q5: OPEN - confirm current product/certificate and actual ID
A6: Panasonic | B6: White Conduit IMC | C6: DWM100Y | D6: 1 | E6: 32.77 | F6: 2.16 | G6: 3025 | H6: 5.23 | I6: 5 | J6: 125 | K6: =E6-2*F6 -> 28.45 | L6: =PI()*K6^2/4 -> 635.70324 | M6: 28.45 | N6: =IF(M6="","",PI()*M6^2/4) -> 635.70324 | O6: UL 1242; catalogue also shows TIS 770 coverage | P6: PDF page 5 (printed pp. 7-8) | Q6: OPEN - confirm current product/certificate and actual ID
A7: Panasonic | B7: White Conduit IMC | C7: DWM114Y | D7: 1-1/4 | E7: 41.59 | F7: 2.16 | G7: 3025 | H7: 7.48 | I7: 3 | J7: 75 | K7: =E7-2*F7 -> 37.27 | L7: =PI()*K7^2/4 -> 1090.9596 | M7: 37.27 | N7: =IF(M7="","",PI()*M7^2/4) -> 1090.9596 | O7: UL 1242; catalogue also shows TIS 770 coverage | P7: PDF page 5 (printed pp. 7-8) | Q7: OPEN - confirm current product/certificate and actual ID
A8: Panasonic | B8: White Conduit IMC | C8: DWM112Y | D8: 1-1/2 | E8: 47.81 | F8: 2.29 | G8: 3025 | H8: 8.67 | I8: 3 | J8: 75 | K8: =E8-2*F8 -> 43.23 | L8: =PI()*K8^2/4 -> 1467.7779 | M8: 43.23 | N8: =IF(M8="","",PI()*M8^2/4) -> 1467.7779 | O8: UL 1242; catalogue also shows TIS 770 coverage | P8: PDF page 5 (printed pp. 7-8) | Q8: OPEN - confirm current product/certificate and actual ID
A9: Panasonic | B9: White Conduit IMC | C9: DWM200Y | D9: 2 | E9: 59.93 | F9: 2.41 | G9: 3025 | H9: 11.65 | J9: 50 | K9: =E9-2*F9 -> 55.11 | L9: =PI()*K9^2/4 -> 2385.3423 | M9: 55.11 | N9: =IF(M9="","",PI()*M9^2/4) -> 2385.3423 | O9: UL 1242; catalogue also shows TIS 770 coverage | P9: PDF page 5 (printed pp. 7-8) | Q9: OPEN - confirm current product/certificate and actual ID
A10: Panasonic | B10: White Conduit IMC | C10: DWM212Y | D10: 2-1/2 | E10: 72.56 | F10: 3.56 | G10: 3010 | H10: 18.71 | J10: 40 | K10: =E10-2*F10 -> 65.44 | L10: =PI()*K10^2/4 -> 3363.3841 | M10: 65.44 | N10: =IF(M10="","",PI()*M10^2/4) -> 3363.3841 | O10: UL 1242; catalogue also shows TIS 770 coverage | P10: PDF page 5 (printed pp. 7-8) | Q10: OPEN - confirm current product/certificate and actual ID
A11: Panasonic | B11: White Conduit IMC | C11: DWM300Y | D11: 3 | E11: 88.29 | F11: 3.56 | G11: 3010 | H11: 22.87 | J11: 30 | K11: =E11-2*F11 -> 81.17 | L11: =PI()*K11^2/4 -> 5174.6499 | M11: 81.17 | N11: =IF(M11="","",PI()*M11^2/4) -> 5174.6499 | O11: UL 1242; catalogue also shows TIS 770 coverage | P11: PDF page 5 (printed pp. 7-8) | Q11: OPEN - confirm current product/certificate and actual ID
A12: Panasonic | B12: White Conduit IMC | C12: DWM312Y | D12: 3-1/2 | E12: 100.86 | F12: 3.56 | G12: 3005 | H12: 26.43 | J12: 20 | K12: =E12-2*F12 -> 93.74 | L12: =PI()*K12^2/4 -> 6901.441 | M12: 93.74 | N12: =IF(M12="","",PI()*M12^2/4) -> 6901.441 | O12: UL 1242; catalogue also shows TIS 770 coverage | P12: PDF page 5 (printed pp. 7-8) | Q12: OPEN - confirm current product/certificate and actual ID
A13: Panasonic | B13: White Conduit IMC | C13: DWM400Y | D13: 4 | E13: 113.4 | F13: 3.56 | G13: 3005 | H13: 29.84 | J13: 15 | K13: =E13-2*F13 -> 106.28 | L13: =PI()*K13^2/4 -> 8871.4166 | M13: 106.28 | N13: =IF(M13="","",PI()*M13^2/4) -> 8871.4166 | O13: UL 1242; catalogue also shows TIS 770 coverage | P13: PDF page 5 (printed pp. 7-8) | Q13: OPEN - confirm current product/certificate and actual ID

Sheet Ladder Data
A1: KJL KLSG - Hot-Dip Galvanized Cable Ladder | B1: KJL KLSG - Hot-Dip Galvanized Cable Ladder | C1: KJL KLSG - Hot-Dip Galvanized Cable Ladder | D1: KJL KLSG - Hot-Dip Galvanized Cable Ladder | E1: KJL KLSG - Hot-Dip Galvanized Cable Ladder | F1: KJL KLSG - Hot-Dip Galvanized Cable Ladder | G1: KJL KLSG - Hot-Dip Galvanized Cable Ladder | H1: KJL KLSG - Hot-Dip Galvanized Cable Ladder | I1: KJL KLSG - Hot-Dip Galvanized Cable Ladder | J1: KJL KLSG - Hot-Dip Galvanized Cable Ladder | K1: KJL KLSG - Hot-Dip Galvanized Cable Ladder | L1: KJL KLSG - Hot-Dip Galvanized Cable Ladder | M1: KJL KLSG - Hot-Dip Galvanized Cable Ladder | N1: KJL KLSG - Hot-Dip Galvanized Cable Ladder | O1: KJL KLSG - Hot-Dip Galvanized Cable Ladder | P1: KJL KLSG - Hot-Dip Galvanized Cable Ladder
A3: Brand | B3: Model code | C3: Nominal width W (mm) | D3: Nominal height H (mm) | E3: Length L (mm) | F3: Steel thickness (mm) | G3: Material | H3: Finish | I3: Coating thickness stated | J3: Confirmed usable width (mm) | K3: Confirmed usable depth (mm) | L3: Usable area if adopted (mm2) | M3: Support span/load rating | N3: Source page | O3: Status | P3: Remark
A4: KJL | B4: KLSG 0200 | C4: 200 | D4: 100 | E4: 3000 | F4: 2 | G4: SPHC hot rolled mild steel sheet | H4: Hot-Dip Galvanized per catalogue | I4: Average 45-60 micron | L4: =IF(OR(J4="",K4=""),"",J4*K4) | M4: TO BE CONFIRMED | N4: PDF pages 122-123 | O4: OPEN | P4: Nominal dimensions are not treated as confirmed usable dimensions.
A5: KJL | B5: KLSG 0300 | C5: 300 | D5: 100 | E5: 3000 | F5: 2 | G5: SPHC hot rolled mild steel sheet | H5: Hot-Dip Galvanized per catalogue | I5: Average 45-60 micron | L5: =IF(OR(J5="",K5=""),"",J5*K5) | M5: TO BE CONFIRMED | N5: PDF pages 122-123 | O5: OPEN | P5: Nominal dimensions are not treated as confirmed usable dimensions.
A6: KJL | B6: KLSG 0400 | C6: 400 | D6: 100 | E6: 3000 | F6: 2 | G6: SPHC hot rolled mild steel sheet | H6: Hot-Dip Galvanized per catalogue | I6: Average 45-60 micron | L6: =IF(OR(J6="",K6=""),"",J6*K6) | M6: TO BE CONFIRMED | N6: PDF pages 122-123 | O6: OPEN | P6: Nominal dimensions are not treated as confirmed usable dimensions.
A7: KJL | B7: KLSG 0500 | C7: 500 | D7: 100 | E7: 3000 | F7: 2 | G7: SPHC hot rolled mild steel sheet | H7: Hot-Dip Galvanized per catalogue | I7: Average 45-60 micron | L7: =IF(OR(J7="",K7=""),"",J7*K7) | M7: TO BE CONFIRMED | N7: PDF pages 122-123 | O7: OPEN | P7: Nominal dimensions are not treated as confirmed usable dimensions.
A8: KJL | B8: KLSG 0600 | C8: 600 | D8: 100 | E8: 3000 | F8: 2 | G8: SPHC hot rolled mild steel sheet | H8: Hot-Dip Galvanized per catalogue | I8: Average 45-60 micron | L8: =IF(OR(J8="",K8=""),"",J8*K8) | M8: TO BE CONFIRMED | N8: PDF pages 122-123 | O8: OPEN | P8: Nominal dimensions are not treated as confirmed usable dimensions.
A9: KJL | B9: KLSG 0700 | C9: 700 | D9: 100 | E9: 3000 | F9: 2 | G9: SPHC hot rolled mild steel sheet | H9: Hot-Dip Galvanized per catalogue | I9: Average 45-60 micron | L9: =IF(OR(J9="",K9=""),"",J9*K9) | M9: TO BE CONFIRMED | N9: PDF pages 122-123 | O9: OPEN | P9: Nominal dimensions are not treated as confirmed usable dimensions.
A10: KJL | B10: KLSG 0800 | C10: 800 | D10: 100 | E10: 3000 | F10: 2 | G10: SPHC hot rolled mild steel sheet | H10: Hot-Dip Galvanized per catalogue | I10: Average 45-60 micron | L10: =IF(OR(J10="",K10=""),"",J10*K10) | M10: TO BE CONFIRMED | N10: PDF pages 122-123 | O10: OPEN | P10: Nominal dimensions are not treated as confirmed usable dimensions.
A11: KJL | B11: KLSG 0900 | C11: 900 | D11: 100 | E11: 3000 | F11: 2 | G11: SPHC hot rolled mild steel sheet | H11: Hot-Dip Galvanized per catalogue | I11: Average 45-60 micron | L11: =IF(OR(J11="",K11=""),"",J11*K11) | M11: TO BE CONFIRMED | N11: PDF pages 122-123 | O11: OPEN | P11: Nominal dimensions are not treated as confirmed usable dimensions.
A12: KJL | B12: KLSG 1000 | C12: 1000 | D12: 100 | E12: 3000 | F12: 2 | G12: SPHC hot rolled mild steel sheet | H12: Hot-Dip Galvanized per catalogue | I12: Average 45-60 micron | L12: =IF(OR(J12="",K12=""),"",J12*K12) | M12: TO BE CONFIRMED | N12: PDF pages 122-123 | O12: OPEN | P12: Nominal dimensions are not treated as confirmed usable dimensions.

Sheet Vendor Register
A1: PV Cable OD Master | editable manufacturer input linked to containment sheets
A3: Cable ID | B3: Manufacturer | C3: Cable type | D3: CSA (mm²) | E3: OD input (mm) | F3: Active downstream | G3: OD source / note
A4: PV-PD-4 | B4: Phelps Dodge | C4: H1Z2Z2-K | D4: 4 | E4: 6 | F4: YES | G4: Phelps_Dodge_PV_Cable_H1Z2Z2-K_Datasheet.pdf; conservative max OD used for screening
A5: PV-PD-6 | B5: Phelps Dodge | C5: H1Z2Z2-K | D5: 6 | E5: 7 | F5: YES | G5: Phelps_Dodge_PV_Cable_H1Z2Z2-K_Datasheet.pdf; conservative max OD used for screening | H5: สาย 6 จาก 6.5 -> 7
A6: PV-PD-10 | B6: Phelps Dodge | C6: H1Z2Z2-K | D6: 10 | E6: 8.2 | F6: YES | G6: Phelps_Dodge_PV_Cable_H1Z2Z2-K_Datasheet.pdf; conservative max OD used for screening
A7: PV-PD-16 | B7: Phelps Dodge | C7: H1Z2Z2-K | D7: 16 | E7: 9.8 | F7: YES | G7: Phelps_Dodge_PV_Cable_H1Z2Z2-K_Datasheet.pdf; conservative max OD used for screening
A8: PV-BK-4 | B8: Bangkok Cable | C8: H1Z2Z2-K | D8: 4 | E8: 6.6 | F8: OPTION | G8: Bangkok_Cable_H1Z2Z2-K_PV_Cable_Datasheet.pdf; conservative max OD used for screening
A9: PV-BK-6 | B9: Bangkok Cable | C9: H1Z2Z2-K | D9: 6 | E9: 7.4 | F9: OPTION | G9: Bangkok_Cable_H1Z2Z2-K_PV_Cable_Datasheet.pdf; conservative max OD used for screening
A10: PV-BK-10 | B10: Bangkok Cable | C10: H1Z2Z2-K | D10: 10 | E10: 8.8 | F10: OPTION | G10: Bangkok_Cable_H1Z2Z2-K_PV_Cable_Datasheet.pdf; conservative max OD used for screening
A11: PV-BK-16 | B11: Bangkok Cable | C11: H1Z2Z2-K | D11: 16 | E11: 10.1 | F11: OPTION | G11: Bangkok_Cable_H1Z2Z2-K_PV_Cable_Datasheet.pdf; conservative max OD used for screening
A16: Owner Vendor List Verification & Reference Datasheet Register | B16: Owner Vendor List Verification & Reference Datasheet Register | C16: Owner Vendor List Verification & Reference Datasheet Register | D16: Owner Vendor List Verification & Reference Datasheet Register | E16: Owner Vendor List Verification & Reference Datasheet Register | F16: Owner Vendor List Verification & Reference Datasheet Register | G16: Owner Vendor List Verification & Reference Datasheet Register | H16: Owner Vendor List Verification & Reference Datasheet Register
A18: Category | B18: Brands in attachment | C18: Reference brand | D18: Reference model/document | E18: Local file | F18: Official source | G18: Review status | H18: Design/procurement note
A19: PV Mounting Structure | B19: Goomax; Chiko; Reddot; Sunforson | C19: Chiko | D19: 7Rail | E19: Datasheet/Vendor_Reference/CHIKO_7Rail_Data_Sheet.pdf | F19: https://www.chikolar.com/ | G19: REFERENCE SCREENED | H19: Exact roof interface, wind load and structural calculation remain project-specific
A20: PV MDB Panel | B20: Precise; Mitsubishi; CPT; Asefa; PMK; Sangchai | C20: — | D20: — | E20: — | F20: — | G20: GAP | H20: Need exact assembly datasheet, IEC 61439 evidence, Icw/Icc, IP, form, busbar and SLD
A21: Weather Sensor | B21: Kipp & Zonen; Hukseflux; Rika; Ingenieurburo | C21: Kipp & Zonen | D21: SMP10x/SMP22x | E21: Datasheet/Vendor_Reference/KippZonen_SMP10x_SMP22x_Datasheet_2025.pdf | F21: https://www.kippzonen.com/ | G21: REFERENCE SCREENED | H21: Select sensor class, output, heating and logger compatibility
A22: Protective Relay | B22: Schneider; Siemens; ABB | C22: Schneider | D22: PowerLogic P3 | E22: Datasheet/Vendor_Reference/Schneider_PowerLogic_P3_Catalog_2024.pdf | F22: https://www.se.com/ | G22: REFERENCE SCREENED | H22: Utility protection functions/settings and CT/VT inputs TBC
A23: Power Meter | B23: Janitza; Schneider; ISKRA | C23: Schneider | D23: PowerLogic PM5000 | E23: Datasheet/Vendor_Reference/Schneider_PM5000_Technical_Datasheet.pdf | F23: https://www.se.com/in/en/download/document/29364262/ | G23: REFERENCE SCREENED | H23: Choose exact PM5xxx model, accuracy class, CT input and protocol
A24: Revenue Meter | B24: EDMI; Landis & Gyr | C24: EDMI | D24: Mk10E | E24: Datasheet/Vendor_Reference/EDMI_Mk10E_Factsheet_Rev02_2025.pdf | F24: https://www.edmi-meters.com/ | G24: REFERENCE SCREENED | H24: Final model and utility approval mandatory
A25: PV Connector | B25: Stäubli (MC) | C25: Stäubli | D25: MC4-Evo 2 | E25: Datasheet/Vendor_Reference/Staubli_MC4-Evo2_Cable_Coupler.pdf | F25: https://www.staubli.com/ | G25: REFERENCE SCREENED | H25: Do not cross-mate unlike brands/models; verify cable OD, crimp tool and certification
A26: PV Cable | B26: Thai Wonderful; Phelps Dodge; Prysmian; Bangkok Cable | C26: Phelps Dodge / Bangkok Cable | D26: H1Z2Z2-K | E26: Phelps_Dodge_PV_Cable_H1Z2Z2-K_Datasheet.pdf; Bangkok_Cable_H1Z2Z2-K_PV_Cable_Datasheet.pdf | F26: https://www.pdcable.com/; https://www.bangkokcable.com/ | G26: SOURCE TRANSFERRED | H26: OD master below is the linked design input for the new containment views; confirm exact project product code before IFC.
A27: AC Cable | B27: Bangkok Cable; Thai Yazaki; Phelps Dodge | C27: Phelps Dodge | D27: CV / CV-FD family | E27: Datasheet/Vendor_Reference/Phelps_Dodge_LV_Power_Control_Cables.pdf | F27: https://www.pdcable.com/product/cv-fd-1/ | G27: REFERENCE SCREENED | H27: Exact FD-CV construction, cores, OD, fire certificate and current rating TBC
A28: Communication Cable | B28: LINK; Belden | C28: Belden | D28: 3106A RS-485 | E28: Datasheet/Vendor_Reference/Belden_3106A_RS485_TechData.pdf | F28: https://www.belden.com/ | G28: REFERENCE SCREENED | H28: Confirm protocol, shield grounding, UV/LSZH/fire requirements and separation
... A33: PV Inverter (additional) | B33: Not listed in attachment | C33: Sungrow | D33: SG125CX-P2 | E33: Datasheet/Vendor_Reference/Sungrow_SG125CX-P2_Datasheet_V12.pdf | F33: https://www.sungrowpower.com/ | G33: OUTSIDE VENDOR LIST | H33: Reference only; utility grid code, MPPT/string limits and protection settings required
A36: Jinko PV Module Datasheet | Selected 725 Wp reference from Workspace
A38: Parameter | B38: Value | C38: Unit | D38: Source / engineering note
A39: Manufacturer | B39: Jinko Solar | C39: — | D39: Workspace datasheet
A40: Model | B40: JKM700-725N-66HL5-BDV-Z2C2-OC | C40: — | D40: Workspace datasheet
A41: Selected Pmax | B41: 725 | C41: Wp | D41: Use 725 Wp STC row
A42: Vmp at STC | B42: 41 | C42: V | D42: Workspace datasheet
A43: Imp at STC | B43: 17.69 | C43: A | D43: Workspace datasheet
A44: Voc at STC | B44: 49.2 | C44: V | D44: Workspace datasheet
A45: Isc at STC | B45: 18.74 | C45: A | D45: Workspace datasheet
A46: Max system voltage | B46: 1500 | C46: V DC | D46: Workspace datasheet
A47: Max series fuse | B47: 35 | C47: A | D47: Workspace datasheet
A48: Minimum cell temperature used in design screens | B48: 10 | C48: °C | D48: Project design input; verify inverter/system design
A49: Source file | B49: 3.2.panel_datasheet_JKM700-725N-66HL5-BDV-Z2C2-OC.pdf | C49: — | D49: Workspace file; verify controlled revision before IFC

Sheet Thermal Check (เลือกสาย)
A1: Thermal / Ampacity Check - Separate from Physical Fill | B1: Thermal / Ampacity Check - Separate from Physical Fill | C1: Thermal / Ampacity Check - Separate from Physical Fill | D1: Thermal / Ampacity Check - Separate from Physical Fill | E1: Thermal / Ampacity Check - Separate from Physical Fill | F1: Thermal / Ampacity Check - Separate from Physical Fill | G1: Thermal / Ampacity Check - Separate from Physical Fill | H1: Thermal / Ampacity Check - Separate from Physical Fill | I1: Thermal / Ampacity Check - Separate from Physical Fill | J1: Thermal / Ampacity Check - Separate from Physical Fill | K1: Thermal / Ampacity Check - Separate from Physical Fill | L1: Thermal / Ampacity Check - Separate from Physical Fill
A2: Three simulated examples are populated below. Base ampacity is taken from the local PV cable datasheet working data; factors are explicit inputs and must be replaced by the project installation calculation.
A3: Circuit ID | B3: Cable model / size | C3: Design current (A) | D3: Base ampacity (A) | E3: Ambient factor | F3: Grouping factor | G3: Other factor | H3: Adjusted ampacity (A) | I3: Result | J3: Ampacity table source | K3: Installation method | L3: Remark
A4: CIR-EX-001 | B4: Phelps Dodge H1Z2Z2-K 4 mm² | C4: 17.69 | D4: 55 | E4: 0.95 | F4: 0.95 | G4: 1 | H4: =IF(OR(D4="",E4="",F4="",G4=""),"",D4*E4*F4*G4) -> 49.6375 | I4: =IF(OR(C4="",H4=""),"REVIEW",IF(H4>=C4,"PASS","FAIL")) -> PASS | J4: Phelps_Dodge_PV_Cable_H1Z2Z2-K_Datasheet.pdf | K4: wireway / ventilated | L4: Example 1; replace with project method
A5: CIR-EX-002 | B5: Phelps Dodge H1Z2Z2-K 6 mm² | C5: 17.69 | D5: 70 | E5: 0.95 | F5: 0.9 | G5: 1 | H5: =IF(OR(D5="",E5="",F5="",G5=""),"",D5*E5*F5*G5) -> 59.85 | I5: =IF(OR(C5="",H5=""),"REVIEW",IF(H5>=C5,"PASS","FAIL")) -> PASS | J5: Phelps_Dodge_PV_Cable_H1Z2Z2-K_Datasheet.pdf | K5: wireway / ventilated | L5: Example 2; replace with project method
A6: CIR-EX-003 | B6: Bangkok Cable H1Z2Z2-K 16 mm² | C6: 100 | D6: 132 | E6: 0.8 | F6: 0.8 | G6: 1 | H6: =IF(OR(D6="",E6="",F6="",G6=""),"",D6*E6*F6*G6) -> 84.48 | I6: =IF(OR(C6="",H6=""),"REVIEW",IF(H6>=C6,"PASS","FAIL")) -> FAIL | J6: Bangkok_Cable_H1Z2Z2-K_PV_Cable_Datasheet.pdf | K6: wireway / ventilated | L6: Example 3 intentionally demonstrates CHECK
A7: CIR-004 | H7: =IF(OR(D7="",E7="",F7="",G7=""),"",D7*E7*F7*G7) | I7: =IF(OR(C7="",H7=""),"REVIEW",IF(H7>=C7,"PASS","FAIL")) -> REVIEW
A8: CIR-005 | H8: =IF(OR(D8="",E8="",F8="",G8=""),"",D8*E8*F8*G8) | I8: =IF(OR(C8="",H8=""),"REVIEW",IF(H8>=C8,"PASS","FAIL")) -> REVIEW
A9: CIR-006 | H9: =IF(OR(D9="",E9="",F9="",G9=""),"",D9*E9*F9*G9) | I9: =IF(OR(C9="",H9=""),"REVIEW",IF(H9>=C9,"PASS","FAIL")) -> REVIEW
A10: CIR-007 | H10: =IF(OR(D10="",E10="",F10="",G10=""),"",D10*E10*F10*G10) | I10: =IF(OR(C10="",H10=""),"REVIEW",IF(H10>=C10,"PASS","FAIL")) -> REVIEW
A11: CIR-008 | H11: =IF(OR(D11="",E11="",F11="",G11=""),"",D11*E11*F11*G11) | I11: =IF(OR(C11="",H11=""),"REVIEW",IF(H11>=C11,"PASS","FAIL")) -> REVIEW
A12: CIR-009 | H12: =IF(OR(D12="",E12="",F12="",G12=""),"",D12*E12*F12*G12) | I12: =IF(OR(C12="",H12=""),"REVIEW",IF(H12>=C12,"PASS","FAIL")) -> REVIEW
A13: CIR-010 | H13: =IF(OR(D13="",E13="",F13="",G13=""),"",D13*E13*F13*G13) | I13: =IF(OR(C13="",H13=""),"REVIEW",IF(H13>=C13,"PASS","FAIL")) -> REVIEW
A14: CIR-011 | H14: =IF(OR(D14="",E14="",F14="",G14=""),"",D14*E14*F14*G14) | I14: =IF(OR(C14="",H14=""),"REVIEW",IF(H14>=C14,"PASS","FAIL")) -> REVIEW
A15: CIR-012 | H15: =IF(OR(D15="",E15="",F15="",G15=""),"",D15*E15*F15*G15) | I15: =IF(OR(C15="",H15=""),"REVIEW",IF(H15>=C15,"PASS","FAIL")) -> REVIEW
A16: CIR-013 | H16: =IF(OR(D16="",E16="",F16="",G16=""),"",D16*E16*F16*G16) | I16: =IF(OR(C16="",H16=""),"REVIEW",IF(H16>=C16,"PASS","FAIL")) -> REVIEW
A17: CIR-014 | H17: =IF(OR(D17="",E17="",F17="",G17=""),"",D17*E17*F17*G17) | I17: =IF(OR(C17="",H17=""),"REVIEW",IF(H17>=C17,"PASS","FAIL")) -> REVIEW
A18: CIR-015 | H18: =IF(OR(D18="",E18="",F18="",G18=""),"",D18*E18*F18*G18) | I18: =IF(OR(C18="",H18=""),"REVIEW",IF(H18>=C18,"PASS","FAIL")) -> REVIEW
... A23: CIR-020 | H23: =IF(OR(D23="",E23="",F23="",G23=""),"",D23*E23*F23*G23) | I23: =IF(OR(C23="",H23=""),"REVIEW",IF(H23>=C23,"PASS","FAIL")) -> REVIEW
B24: *ตรวจสอบ Spec. สายไฟว่าเพียงพอหรือไม่

Sheet 1.IMC Max Count
A1: Maximum Cable Count in Panasonic IMC - EIT Physical Fill Screening | B1: Maximum Cable Count in Panasonic IMC - EIT Physical Fill Screening | C1: Maximum Cable Count in Panasonic IMC - EIT Physical Fill Screening | D1: Maximum Cable Count in Panasonic IMC - EIT Physical Fill Screening | E1: Maximum Cable Count in Panasonic IMC - EIT Physical Fill Screening | F1: Maximum Cable Count in Panasonic IMC - EIT Physical Fill Screening | G1: Maximum Cable Count in Panasonic IMC - EIT Physical Fill Screening | H1: Maximum Cable Count in Panasonic IMC - EIT Physical Fill Screening | I1: Maximum Cable Count in Panasonic IMC - EIT Physical Fill Screening | J1: Maximum Cable Count in Panasonic IMC - EIT Physical Fill Screening | K1: Maximum Cable Count in Panasonic IMC - EIT Physical Fill Screening | L1: Maximum Cable Count in Panasonic IMC - EIT Physical Fill Screening | M1: Maximum Cable Count in Panasonic IMC - EIT Physical Fill Screening | N1: Maximum Cable Count in Panasonic IMC - EIT Physical Fill Screening | O1: Maximum Cable Count in Panasonic IMC - EIT Physical Fill Screening | P1: Maximum Cable Count in Panasonic IMC - EIT Physical Fill Screening
A2: Rev.4: IMC fill screening is governed by the number of cable pieces (Qty). Cores/cable is informational only. The left matrix gives maximum Qty by IMC size; the right matrix uses that left Qty to show total fill %. Actual certified IMC ID is required before IFC. | B2: วสท. 022001-22 ตาราง 5-3: 1 เส้น 53%, 2 เส้น 31%, 3 เส้นขึ้นไป 40%. ตารางนี้แสดงจำนวนสาย/เคเบิลเป็นชิ้น ไม่ใช่จำนวนวงจร และยังไม่รวม ampacity/grouping/bending/pulling checks | C2: วสท. 022001-22 ตาราง 5-3: 1 เส้น 53%, 2 เส้น 31%, 3 เส้นขึ้นไป 40%. ตารางนี้แสดงจำนวนสาย/เคเบิลเป็นชิ้น ไม่ใช่จำนวนวงจร และยังไม่รวม ampacity/grouping/bending/pulling checks | D2: วสท. 022001-22 ตาราง 5-3: 1 เส้น 53%, 2 เส้น 31%, 3 เส้นขึ้นไป 40%. ตารางนี้แสดงจำนวนสาย/เคเบิลเป็นชิ้น ไม่ใช่จำนวนวงจร และยังไม่รวม ampacity/grouping/bending/pulling checks | E2: วสท. 022001-22 ตาราง 5-3: 1 เส้น 53%, 2 เส้น 31%, 3 เส้นขึ้นไป 40%. ตารางนี้แสดงจำนวนสาย/เคเบิลเป็นชิ้น ไม่ใช่จำนวนวงจร และยังไม่รวม ampacity/grouping/bending/pulling checks | F2: วสท. 022001-22 ตาราง 5-3: 1 เส้น 53%, 2 เส้น 31%, 3 เส้นขึ้นไป 40%. ตารางนี้แสดงจำนวนสาย/เคเบิลเป็นชิ้น ไม่ใช่จำนวนวงจร และยังไม่รวม ampacity/grouping/bending/pulling checks | G2: วสท. 022001-22 ตาราง 5-3: 1 เส้น 53%, 2 เส้น 31%, 3 เส้นขึ้นไป 40%. ตารางนี้แสดงจำนวนสาย/เคเบิลเป็นชิ้น ไม่ใช่จำนวนวงจร และยังไม่รวม ampacity/grouping/bending/pulling checks | H2: วสท. 022001-22 ตาราง 5-3: 1 เส้น 53%, 2 เส้น 31%, 3 เส้นขึ้นไป 40%. ตารางนี้แสดงจำนวนสาย/เคเบิลเป็นชิ้น ไม่ใช่จำนวนวงจร และยังไม่รวม ampacity/grouping/bending/pulling checks | I2: วสท. 022001-22 ตาราง 5-3: 1 เส้น 53%, 2 เส้น 31%, 3 เส้นขึ้นไป 40%. ตารางนี้แสดงจำนวนสาย/เคเบิลเป็นชิ้น ไม่ใช่จำนวนวงจร และยังไม่รวม ampacity/grouping/bending/pulling checks | J2: วสท. 022001-22 ตาราง 5-3: 1 เส้น 53%, 2 เส้น 31%, 3 เส้นขึ้นไป 40%. ตารางนี้แสดงจำนวนสาย/เคเบิลเป็นชิ้น ไม่ใช่จำนวนวงจร และยังไม่รวม ampacity/grouping/bending/pulling checks | K2: วสท. 022001-22 ตาราง 5-3: 1 เส้น 53%, 2 เส้น 31%, 3 เส้นขึ้นไป 40%. ตารางนี้แสดงจำนวนสาย/เคเบิลเป็นชิ้น ไม่ใช่จำนวนวงจร และยังไม่รวม ampacity/grouping/bending/pulling checks | L2: วสท. 022001-22 ตาราง 5-3: 1 เส้น 53%, 2 เส้น 31%, 3 เส้นขึ้นไป 40%. ตารางนี้แสดงจำนวนสาย/เคเบิลเป็นชิ้น ไม่ใช่จำนวนวงจร และยังไม่รวม ampacity/grouping/bending/pulling checks | M2: วสท. 022001-22 ตาราง 5-3: 1 เส้น 53%, 2 เส้น 31%, 3 เส้นขึ้นไป 40%. ตารางนี้แสดงจำนวนสาย/เคเบิลเป็นชิ้น ไม่ใช่จำนวนวงจร และยังไม่รวม ampacity/grouping/bending/pulling checks | N2: วสท. 022001-22 ตาราง 5-3: 1 เส้น 53%, 2 เส้น 31%, 3 เส้นขึ้นไป 40%. ตารางนี้แสดงจำนวนสาย/เคเบิลเป็นชิ้น ไม่ใช่จำนวนวงจร และยังไม่รวม ampacity/grouping/bending/pulling checks | O2: วสท. 022001-22 ตาราง 5-3: 1 เส้น 53%, 2 เส้น 31%, 3 เส้นขึ้นไป 40%. ตารางนี้แสดงจำนวนสาย/เคเบิลเป็นชิ้น ไม่ใช่จำนวนวงจร และยังไม่รวม ampacity/grouping/bending/pulling checks | P2: วสท. 022001-22 ตาราง 5-3: 1 เส้น 53%, 2 เส้น 31%, 3 เส้นขึ้นไป 40%. ตารางนี้แสดงจำนวนสาย/เคเบิลเป็นชิ้น ไม่ใช่จำนวนวงจร และยังไม่รวม ampacity/grouping/bending/pulling checks
A3: IMC internal ID เป็น screening = Panasonic catalogue OD - 2 x minimum wall thickness; ต้องเปลี่ยนเป็น actual certified ID ก่อน issue design. ค่า 0 = ใส่ไม่ได้ตาม physical fill ของท่อขนาดนั้น | B3: IMC internal ID เป็น screening = Panasonic catalogue OD - 2 x minimum wall thickness; ต้องเปลี่ยนเป็น actual certified ID ก่อน issue design. ค่า 0 = ใส่ไม่ได้ตาม physical fill ของท่อขนาดนั้น | C3: IMC internal ID เป็น screening = Panasonic catalogue OD - 2 x minimum wall thickness; ต้องเปลี่ยนเป็น actual certified ID ก่อน issue design. ค่า 0 = ใส่ไม่ได้ตาม physical fill ของท่อขนาดนั้น | D3: IMC internal ID เป็น screening = Panasonic catalogue OD - 2 x minimum wall thickness; ต้องเปลี่ยนเป็น actual certified ID ก่อน issue design. ค่า 0 = ใส่ไม่ได้ตาม physical fill ของท่อขนาดนั้น | E3: IMC internal ID เป็น screening = Panasonic catalogue OD - 2 x minimum wall thickness; ต้องเปลี่ยนเป็น actual certified ID ก่อน issue design. ค่า 0 = ใส่ไม่ได้ตาม physical fill ของท่อขนาดนั้น | F3: IMC internal ID เป็น screening = Panasonic catalogue OD - 2 x minimum wall thickness; ต้องเปลี่ยนเป็น actual certified ID ก่อน issue design. ค่า 0 = ใส่ไม่ได้ตาม physical fill ของท่อขนาดนั้น | G3: IMC internal ID เป็น screening = Panasonic catalogue OD - 2 x minimum wall thickness; ต้องเปลี่ยนเป็น actual certified ID ก่อน issue design. ค่า 0 = ใส่ไม่ได้ตาม physical fill ของท่อขนาดนั้น | H3: IMC internal ID เป็น screening = Panasonic catalogue OD - 2 x minimum wall thickness; ต้องเปลี่ยนเป็น actual certified ID ก่อน issue design. ค่า 0 = ใส่ไม่ได้ตาม physical fill ของท่อขนาดนั้น | I3: IMC internal ID เป็น screening = Panasonic catalogue OD - 2 x minimum wall thickness; ต้องเปลี่ยนเป็น actual certified ID ก่อน issue design. ค่า 0 = ใส่ไม่ได้ตาม physical fill ของท่อขนาดนั้น | J3: IMC internal ID เป็น screening = Panasonic catalogue OD - 2 x minimum wall thickness; ต้องเปลี่ยนเป็น actual certified ID ก่อน issue design. ค่า 0 = ใส่ไม่ได้ตาม physical fill ของท่อขนาดนั้น | K3: IMC internal ID เป็น screening = Panasonic catalogue OD - 2 x minimum wall thickness; ต้องเปลี่ยนเป็น actual certified ID ก่อน issue design. ค่า 0 = ใส่ไม่ได้ตาม physical fill ของท่อขนาดนั้น | L3: IMC internal ID เป็น screening = Panasonic catalogue OD - 2 x minimum wall thickness; ต้องเปลี่ยนเป็น actual certified ID ก่อน issue design. ค่า 0 = ใส่ไม่ได้ตาม physical fill ของท่อขนาดนั้น | M3: IMC internal ID เป็น screening = Panasonic catalogue OD - 2 x minimum wall thickness; ต้องเปลี่ยนเป็น actual certified ID ก่อน issue design. ค่า 0 = ใส่ไม่ได้ตาม physical fill ของท่อขนาดนั้น | N3: IMC internal ID เป็น screening = Panasonic catalogue OD - 2 x minimum wall thickness; ต้องเปลี่ยนเป็น actual certified ID ก่อน issue design. ค่า 0 = ใส่ไม่ได้ตาม physical fill ของท่อขนาดนั้น | O3: IMC internal ID เป็น screening = Panasonic catalogue OD - 2 x minimum wall thickness; ต้องเปลี่ยนเป็น actual certified ID ก่อน issue design. ค่า 0 = ใส่ไม่ได้ตาม physical fill ของท่อขนาดนั้น | P3: IMC internal ID เป็น screening = Panasonic catalogue OD - 2 x minimum wall thickness; ต้องเปลี่ยนเป็น actual certified ID ก่อน issue design. ค่า 0 = ใส่ไม่ได้ตาม physical fill ของท่อขนาดนั้น
A4: Qty 1 = 53%, Qty 2 = 31%, Qty 3 or more = 40%
A5: Panasonic IMC trade size | B5: Panasonic IMC trade size | C5: Panasonic IMC trade size | D5: Panasonic IMC trade size | E5: Panasonic IMC trade size | F5: Panasonic IMC trade size | G5: 1/2 in | H5: 3/4 in | I5: 1 in | J5: 1-1/4 in | K5: 1-1/2 in | L5: 2 in | M5: 2-1/2 in | N5: 3 in | O5: 3-1/2 in | P5: 4 in | Q5: Added comparison: total fill at the maximum Qty from the left matrix
A6: Screening internal ID (mm) | B6: Screening internal ID (mm) | C6: Screening internal ID (mm) | D6: Screening internal ID (mm) | E6: Screening internal ID (mm) | F6: Screening internal ID (mm) | G6: ='Conduit Data'!M4 -> 17.12 | H6: ='Conduit Data'!M5 -> 22.34 | I6: ='Conduit Data'!M6 -> 28.45 | J6: ='Conduit Data'!M7 -> 37.27 | K6: ='Conduit Data'!M8 -> 43.23 | L6: ='Conduit Data'!M9 -> 55.11 | M6: ='Conduit Data'!M10 -> 65.44 | N6: ='Conduit Data'!M11 -> 81.17 | O6: ='Conduit Data'!M12 -> 93.74 | P6: ='Conduit Data'!M13 -> 106.28 | R6: Formula = left-table Qty × cable area / IMC internal area. This is the full fill percentage for the Qty shown in the left table, not a one-cable ratio.
A7: Internal area (mm²) | B7: Internal area (mm²) | C7: Internal area (mm²) | D7: Internal area (mm²) | E7: Internal area (mm²) | F7: Internal area (mm²) | G7: =PI()*G6^2/4 -> 230.1958 | H7: =PI()*H6^2/4 -> 391.97306 | I7: =PI()*I6^2/4 -> 635.70324 | J7: =PI()*J6^2/4 -> 1090.9596 | K7: =PI()*K6^2/4 -> 1467.7779 | L7: =PI()*L6^2/4 -> 2385.3423 | M7: =PI()*M6^2/4 -> 3363.3841 | N7: =PI()*N6^2/4 -> 5174.6499 | ... P7: =PI()*P6^2/4 -> 8871.4166
A9: System | B9: Cable family | C9: Cores / cable (info.) | D9: CSA mm² | E9: OD mm | F9: Cable area mm² | G9: 1/2 in | H9: 3/4 in | I9: 1 in | J9: 1-1/4 in | K9: 1-1/2 in | L9: 2 in | M9: 2-1/2 in | N9: 3 in | O9: 3-1/2 in | P9: 4 in | Q9: Cable / row | R9: 1/2 in | S9: 3/4 in | T9: 1 in | U9: 1-1/4 in | V9: 1-1/2 in | W9: 2 in | X9: 2-1/2 in | Y9: 3 in | Z9: 3-1/2 in | AA9: 4 in
A10: PV | B10: Phelps Dodge H1Z2Z2-K 4 mm² | C10: 1 | D10: 4 | E10: ='Vendor Register'!$E$4 -> 6 | F10: =PI()*E10^2/4 -> 28.274334 | G10: =IF(G$7="",0,IF(INT(0.4*G$7/$F10)>=3,INT(0.4*G$7/$F10),IF(INT(0.31*G$7/$F10)>=2,2,IF(0.53*G$7/$F10>=1,1,0)))) -> 3 | H10: =IF(H$7="",0,IF(INT(0.4*H$7/$F10)>=3,INT(0.4*H$7/$F10),IF(INT(0.31*H$7/$F10)>=2,2,IF(0.53*H$7/$F10>=1,1,0)))) -> 5 | I10: =IF(I$7="",0,IF(INT(0.4*I$7/$F10)>=3,INT(0.4*I$7/$F10),IF(INT(0.31*I$7/$F10)>=2,2,IF(0.53*I$7/$F10>=1,1,0)))) -> 8 | J10: =IF(J$7="",0,IF(INT(0.4*J$7/$F10)>=3,INT(0.4*J$7/$F10),IF(INT(0.31*J$7/$F10)>=2,2,IF(0.53*J$7/$F10>=1,1,0)))) -> 15 | K10: =IF(K$7="",0,IF(INT(0.4*K$7/$F10)>=3,INT(0.4*K$7/$F10),IF(INT(0.31*K$7/$F10)>=2,2,IF(0.53*K$7/$F10>=1,1,0)))) -> 20 | L10: =IF(L$7="",0,IF(INT(0.4*L$7/$F10)>=3,INT(0.4*L$7/$F10),IF(INT(0.31*L$7/$F10)>=2,2,IF(0.53*L$7/$F10>=1,1,0)))) -> 33 | M10: =IF(M$7="",0,IF(INT(0.4*M$7/$F10)>=3,INT(0.4*M$7/$F10),IF(INT(0.31*M$7/$F10)>=2,2,IF(0.53*M$7/$F10>=1,1,0)))) -> 47 | N10: =IF(N$7="",0,IF(INT(0.4*N$7/$F10)>=3,INT(0.4*N$7/$F10),IF(INT(0.31*N$7/$F10)>=2,2,IF(0.53*N$7/$F10>=1,1,0)))) -> 73 | ... P10: =IF(P$7="",0,IF(INT(0.4*P$7/$F10)>=3,INT(0.4*P$7/$F10),IF(INT(0.31*P$7/$F10)>=2,2,IF(0.53*P$7/$F10>=1,1,0)))) -> 125 | Q10: =B10 -> Phelps Dodge H1Z2Z2-K 4 mm² | R10: =IFERROR($G10*$F10/G$7,"") -> 0.36848196 | S10: =IFERROR($H10*$F10/H$7,"") -> 0.3606668 | T10: =IFERROR($I10*$F10/I$7,"") -> 0.35581803 | U10: =IFERROR($J10*$F10/J$7,"") -> 0.38875409 | V10: =IFERROR($K10*$F10/K$7,"") -> 0.38526719 | W10: =IFERROR($L10*$F10/L$7,"") -> 0.39116106 | X10: =IFERROR($M10*$F10/M$7,"") -> 0.39510614 | Y10: =IFERROR($N10*$F10/N$7,"") -> 0.39887266 | Z10: =IFERROR($O10*$F10/O$7,"") -> 0.39739677 | AA10: =IFERROR($P10*$F10/P$7,"") -> 0.39839091
A11: PV | B11: Phelps Dodge H1Z2Z2-K 6 mm² | C11: 1 | D11: 6 | E11: ='Vendor Register'!$E$5 -> 7 | F11: =PI()*E11^2/4 -> 38.48451 | G11: =IF(G$7="",0,IF(INT(0.4*G$7/$F11)>=3,INT(0.4*G$7/$F11),IF(INT(0.31*G$7/$F11)>=2,2,IF(0.53*G$7/$F11>=1,1,0)))) -> 1 | H11: =IF(H$7="",0,IF(INT(0.4*H$7/$F11)>=3,INT(0.4*H$7/$F11),IF(INT(0.31*H$7/$F11)>=2,2,IF(0.53*H$7/$F11>=1,1,0)))) -> 4 | I11: =IF(I$7="",0,IF(INT(0.4*I$7/$F11)>=3,INT(0.4*I$7/$F11),IF(INT(0.31*I$7/$F11)>=2,2,IF(0.53*I$7/$F11>=1,1,0)))) -> 6 | J11: =IF(J$7="",0,IF(INT(0.4*J$7/$F11)>=3,INT(0.4*J$7/$F11),IF(INT(0.31*J$7/$F11)>=2,2,IF(0.53*J$7/$F11>=1,1,0)))) -> 11 | K11: =IF(K$7="",0,IF(INT(0.4*K$7/$F11)>=3,INT(0.4*K$7/$F11),IF(INT(0.31*K$7/$F11)>=2,2,IF(0.53*K$7/$F11>=1,1,0)))) -> 15 | L11: =IF(L$7="",0,IF(INT(0.4*L$7/$F11)>=3,INT(0.4*L$7/$F11),IF(INT(0.31*L$7/$F11)>=2,2,IF(0.53*L$7/$F11>=1,1,0)))) -> 24 | M11: =IF(M$7="",0,IF(INT(0.4*M$7/$F11)>=3,INT(0.4*M$7/$F11),IF(INT(0.31*M$7/$F11)>=2,2,IF(0.53*M$7/$F11>=1,1,0)))) -> 34 | N11: =IF(N$7="",0,IF(INT(0.4*N$7/$F11)>=3,INT(0.4*N$7/$F11),IF(INT(0.31*N$7/$F11)>=2,2,IF(0.53*N$7/$F11>=1,1,0)))) -> 53 | ... P11: =IF(P$7="",0,IF(INT(0.4*P$7/$F11)>=3,INT(0.4*P$7/$F11),IF(INT(0.31*P$7/$F11)>=2,2,IF(0.53*P$7/$F11>=1,1,0)))) -> 92 | Q11: =B11 -> Phelps Dodge H1Z2Z2-K 6 mm² | R11: =IFERROR($G11*$F11/G$7,"") -> 0.16718163 | S11: =IFERROR($H11*$F11/H$7,"") -> 0.39272607 | T11: =IFERROR($I11*$F11/I$7,"") -> 0.3632309 | U11: =IFERROR($J11*$F11/J$7,"") -> 0.38803418 | V11: =IFERROR($K11*$F11/K$7,"") -> 0.39329359 | W11: =IFERROR($L11*$F11/L$7,"") -> 0.38720994 | X11: =IFERROR($M11*$F11/M$7,"") -> 0.38903477 | Y11: =IFERROR($N11*$F11/N$7,"") -> 0.39416754 | Z11: =IFERROR($O11*$F11/O$7,"") -> 0.39591735 | AA11: =IFERROR($P11*$F11/P$7,"") -> 0.39909916
A12: PV | B12: Phelps Dodge H1Z2Z2-K 10 mm² | C12: 1 | D12: 10 | E12: ='Vendor Register'!$E$6 -> 8.2 | F12: =PI()*E12^2/4 -> 52.810173 | G12: =IF(G$7="",0,IF(INT(0.4*G$7/$F12)>=3,INT(0.4*G$7/$F12),IF(INT(0.31*G$7/$F12)>=2,2,IF(0.53*G$7/$F12>=1,1,0)))) -> 1 | H12: =IF(H$7="",0,IF(INT(0.4*H$7/$F12)>=3,INT(0.4*H$7/$F12),IF(INT(0.31*H$7/$F12)>=2,2,IF(0.53*H$7/$F12>=1,1,0)))) -> 2 | I12: =IF(I$7="",0,IF(INT(0.4*I$7/$F12)>=3,INT(0.4*I$7/$F12),IF(INT(0.31*I$7/$F12)>=2,2,IF(0.53*I$7/$F12>=1,1,0)))) -> 4 | J12: =IF(J$7="",0,IF(INT(0.4*J$7/$F12)>=3,INT(0.4*J$7/$F12),IF(INT(0.31*J$7/$F12)>=2,2,IF(0.53*J$7/$F12>=1,1,0)))) -> 8 | K12: =IF(K$7="",0,IF(INT(0.4*K$7/$F12)>=3,INT(0.4*K$7/$F12),IF(INT(0.31*K$7/$F12)>=2,2,IF(0.53*K$7/$F12>=1,1,0)))) -> 11 | L12: =IF(L$7="",0,IF(INT(0.4*L$7/$F12)>=3,INT(0.4*L$7/$F12),IF(INT(0.31*L$7/$F12)>=2,2,IF(0.53*L$7/$F12>=1,1,0)))) -> 18 | M12: =IF(M$7="",0,IF(INT(0.4*M$7/$F12)>=3,INT(0.4*M$7/$F12),IF(INT(0.31*M$7/$F12)>=2,2,IF(0.53*M$7/$F12>=1,1,0)))) -> 25 | N12: =IF(N$7="",0,IF(INT(0.4*N$7/$F12)>=3,INT(0.4*N$7/$F12),IF(INT(0.31*N$7/$F12)>=2,2,IF(0.53*N$7/$F12>=1,1,0)))) -> 39 | ... P12: =IF(P$7="",0,IF(INT(0.4*P$7/$F12)>=3,INT(0.4*P$7/$F12),IF(INT(0.31*P$7/$F12)>=2,2,IF(0.53*P$7/$F12>=1,1,0)))) -> 67 | Q12: =B12 -> Phelps Dodge H1Z2Z2-K 10 mm² | R12: =IFERROR($G12*$F12/G$7,"") -> 0.22941414 | S12: =IFERROR($H12*$F12/H$7,"") -> 0.26945817 | T12: =IFERROR($I12*$F12/I$7,"") -> 0.3322945 | U12: =IFERROR($J12*$F12/J$7,"") -> 0.38725667 | V12: =IFERROR($K12*$F12/K$7,"") -> 0.39577642 | W12: =IFERROR($L12*$F12/L$7,"") -> 0.39851015 | X12: =IFERROR($M12*$F12/M$7,"") -> 0.39253748 | Y12: =IFERROR($N12*$F12/N$7,"") -> 0.39801663 | Z12: =IFERROR($O12*$F12/O$7,"") -> 0.39790661 | AA12: =IFERROR($P12*$F12/P$7,"") -> 0.39884065
A13: PV | B13: Phelps Dodge H1Z2Z2-K 16 mm² | C13: 1 | D13: 16 | E13: ='Vendor Register'!$E$7 -> 9.8 | F13: =PI()*E13^2/4 -> 75.42964 | G13: =IF(G$7="",0,IF(INT(0.4*G$7/$F13)>=3,INT(0.4*G$7/$F13),IF(INT(0.31*G$7/$F13)>=2,2,IF(0.53*G$7/$F13>=1,1,0)))) -> 1 | H13: =IF(H$7="",0,IF(INT(0.4*H$7/$F13)>=3,INT(0.4*H$7/$F13),IF(INT(0.31*H$7/$F13)>=2,2,IF(0.53*H$7/$F13>=1,1,0)))) -> 1 | I13: =IF(I$7="",0,IF(INT(0.4*I$7/$F13)>=3,INT(0.4*I$7/$F13),IF(INT(0.31*I$7/$F13)>=2,2,IF(0.53*I$7/$F13>=1,1,0)))) -> 3 | J13: =IF(J$7="",0,IF(INT(0.4*J$7/$F13)>=3,INT(0.4*J$7/$F13),IF(INT(0.31*J$7/$F13)>=2,2,IF(0.53*J$7/$F13>=1,1,0)))) -> 5 | K13: =IF(K$7="",0,IF(INT(0.4*K$7/$F13)>=3,INT(0.4*K$7/$F13),IF(INT(0.31*K$7/$F13)>=2,2,IF(0.53*K$7/$F13>=1,1,0)))) -> 7 | L13: =IF(L$7="",0,IF(INT(0.4*L$7/$F13)>=3,INT(0.4*L$7/$F13),IF(INT(0.31*L$7/$F13)>=2,2,IF(0.53*L$7/$F13>=1,1,0)))) -> 12 | M13: =IF(M$7="",0,IF(INT(0.4*M$7/$F13)>=3,INT(0.4*M$7/$F13),IF(INT(0.31*M$7/$F13)>=2,2,IF(0.53*M$7/$F13>=1,1,0)))) -> 17 | N13: =IF(N$7="",0,IF(INT(0.4*N$7/$F13)>=3,INT(0.4*N$7/$F13),IF(INT(0.31*N$7/$F13)>=2,2,IF(0.53*N$7/$F13>=1,1,0)))) -> 27 | ... P13: =IF(P$7="",0,IF(INT(0.4*P$7/$F13)>=3,INT(0.4*P$7/$F13),IF(INT(0.31*P$7/$F13)>=2,2,IF(0.53*P$7/$F13>=1,1,0)))) -> 47 | Q13: =B13 -> Phelps Dodge H1Z2Z2-K 16 mm² | R13: =IFERROR($G13*$F13/G$7,"") -> 0.327676 | S13: =IFERROR($H13*$F13/H$7,"") -> 0.19243578 | T13: =IFERROR($I13*$F13/I$7,"") -> 0.35596628 | U13: =IFERROR($J13*$F13/J$7,"") -> 0.34570318 | V13: =IFERROR($K13*$F13/K$7,"") -> 0.35973254 | W13: =IFERROR($L13*$F13/L$7,"") -> 0.37946574 | X13: =IFERROR($M13*$F13/M$7,"") -> 0.38125407 | Y13: =IFERROR($N13*$F13/N$7,"") -> 0.39357257 | Z13: =IFERROR($O13*$F13/O$7,"") -> 0.39346377 | AA13: =IFERROR($P13*$F13/P$7,"") -> 0.39961973
A14: AC | B14: Phelps Dodge CV/CV-FD-1C | 25 mm² | C14: 1 | D14: 25 | E14: 12 | F14: =PI()*E14^2/4 -> 113.09734 | G14: =IF(G$7="",0,IF(INT(0.4*G$7/$F14)>=3,INT(0.4*G$7/$F14),IF(INT(0.31*G$7/$F14)>=2,2,IF(0.53*G$7/$F14>=1,1,0)))) -> 1 | H14: =IF(H$7="",0,IF(INT(0.4*H$7/$F14)>=3,INT(0.4*H$7/$F14),IF(INT(0.31*H$7/$F14)>=2,2,IF(0.53*H$7/$F14>=1,1,0)))) -> 1 | I14: =IF(I$7="",0,IF(INT(0.4*I$7/$F14)>=3,INT(0.4*I$7/$F14),IF(INT(0.31*I$7/$F14)>=2,2,IF(0.53*I$7/$F14>=1,1,0)))) -> 1 | J14: =IF(J$7="",0,IF(INT(0.4*J$7/$F14)>=3,INT(0.4*J$7/$F14),IF(INT(0.31*J$7/$F14)>=2,2,IF(0.53*J$7/$F14>=1,1,0)))) -> 3 | K14: =IF(K$7="",0,IF(INT(0.4*K$7/$F14)>=3,INT(0.4*K$7/$F14),IF(INT(0.31*K$7/$F14)>=2,2,IF(0.53*K$7/$F14>=1,1,0)))) -> 5 | L14: =IF(L$7="",0,IF(INT(0.4*L$7/$F14)>=3,INT(0.4*L$7/$F14),IF(INT(0.31*L$7/$F14)>=2,2,IF(0.53*L$7/$F14>=1,1,0)))) -> 8 | M14: =IF(M$7="",0,IF(INT(0.4*M$7/$F14)>=3,INT(0.4*M$7/$F14),IF(INT(0.31*M$7/$F14)>=2,2,IF(0.53*M$7/$F14>=1,1,0)))) -> 11 | N14: =IF(N$7="",0,IF(INT(0.4*N$7/$F14)>=3,INT(0.4*N$7/$F14),IF(INT(0.31*N$7/$F14)>=2,2,IF(0.53*N$7/$F14>=1,1,0)))) -> 18 | ... P14: =IF(P$7="",0,IF(INT(0.4*P$7/$F14)>=3,INT(0.4*P$7/$F14),IF(INT(0.31*P$7/$F14)>=2,2,IF(0.53*P$7/$F14>=1,1,0)))) -> 31 | R14: =IFERROR($G14*$F14/G$7,"") -> 0.49130928 | S14: =IFERROR($H14*$F14/H$7,"") -> 0.28853344 | T14: =IFERROR($I14*$F14/I$7,"") -> 0.17790901 | U14: =IFERROR($J14*$F14/J$7,"") -> 0.31100327 | V14: =IFERROR($K14*$F14/K$7,"") -> 0.38526719 | W14: =IFERROR($L14*$F14/L$7,"") -> 0.3793077 | X14: =IFERROR($M14*$F14/M$7,"") -> 0.3698866 | Y14: =IFERROR($N14*$F14/N$7,"") -> 0.39340865 | Z14: =IFERROR($O14*$F14/O$7,"") -> 0.3932999 | AA14: =IFERROR($P14*$F14/P$7,"") -> 0.39520378
A15: AC | B15: Phelps Dodge CV/CV-FD-1C | 35 mm² | C15: 1 | D15: 35 | E15: 13 | F15: =PI()*E15^2/4 -> 132.73229 | G15: =IF(G$7="",0,IF(INT(0.4*G$7/$F15)>=3,INT(0.4*G$7/$F15),IF(INT(0.31*G$7/$F15)>=2,2,IF(0.53*G$7/$F15>=1,1,0)))) -> 0 | H15: =IF(H$7="",0,IF(INT(0.4*H$7/$F15)>=3,INT(0.4*H$7/$F15),IF(INT(0.31*H$7/$F15)>=2,2,IF(0.53*H$7/$F15>=1,1,0)))) -> 1 | I15: =IF(I$7="",0,IF(INT(0.4*I$7/$F15)>=3,INT(0.4*I$7/$F15),IF(INT(0.31*I$7/$F15)>=2,2,IF(0.53*I$7/$F15>=1,1,0)))) -> 1 | J15: =IF(J$7="",0,IF(INT(0.4*J$7/$F15)>=3,INT(0.4*J$7/$F15),IF(INT(0.31*J$7/$F15)>=2,2,IF(0.53*J$7/$F15>=1,1,0)))) -> 3 | K15: =IF(K$7="",0,IF(INT(0.4*K$7/$F15)>=3,INT(0.4*K$7/$F15),IF(INT(0.31*K$7/$F15)>=2,2,IF(0.53*K$7/$F15>=1,1,0)))) -> 4 | L15: =IF(L$7="",0,IF(INT(0.4*L$7/$F15)>=3,INT(0.4*L$7/$F15),IF(INT(0.31*L$7/$F15)>=2,2,IF(0.53*L$7/$F15>=1,1,0)))) -> 7 | M15: =IF(M$7="",0,IF(INT(0.4*M$7/$F15)>=3,INT(0.4*M$7/$F15),IF(INT(0.31*M$7/$F15)>=2,2,IF(0.53*M$7/$F15>=1,1,0)))) -> 10 | N15: =IF(N$7="",0,IF(INT(0.4*N$7/$F15)>=3,INT(0.4*N$7/$F15),IF(INT(0.31*N$7/$F15)>=2,2,IF(0.53*N$7/$F15>=1,1,0)))) -> 15 | ... P15: =IF(P$7="",0,IF(INT(0.4*P$7/$F15)>=3,INT(0.4*P$7/$F15),IF(INT(0.31*P$7/$F15)>=2,2,IF(0.53*P$7/$F15>=1,1,0)))) -> 26 | R15: =IFERROR($G15*$F15/G$7,"") -> 0 | S15: =IFERROR($H15*$F15/H$7,"") -> 0.33862605 | T15: =IFERROR($I15*$F15/I$7,"") -> 0.20879599 | U15: =IFERROR($J15*$F15/J$7,"") -> 0.3649969 | V15: =IFERROR($K15*$F15/K$7,"") -> 0.36172308 | W15: =IFERROR($L15*$F15/L$7,"") -> 0.38951476 | X15: =IFERROR($M15*$F15/M$7,"") -> 0.39463911 | Y15: =IFERROR($N15*$F15/N$7,"") -> 0.3847573 | Z15: =IFERROR($O15*$F15/O$7,"") -> 0.38465094 | AA15: =IFERROR($P15*$F15/P$7,"") -> 0.38900659
A16: AC | B16: Phelps Dodge CV/CV-FD-1C | 50 mm² | C16: 1 | D16: 50 | E16: 15 | F16: =PI()*E16^2/4 -> 176.71459 | G16: =IF(G$7="",0,IF(INT(0.4*G$7/$F16)>=3,INT(0.4*G$7/$F16),IF(INT(0.31*G$7/$F16)>=2,2,IF(0.53*G$7/$F16>=1,1,0)))) -> 0 | H16: =IF(H$7="",0,IF(INT(0.4*H$7/$F16)>=3,INT(0.4*H$7/$F16),IF(INT(0.31*H$7/$F16)>=2,2,IF(0.53*H$7/$F16>=1,1,0)))) -> 1 | I16: =IF(I$7="",0,IF(INT(0.4*I$7/$F16)>=3,INT(0.4*I$7/$F16),IF(INT(0.31*I$7/$F16)>=2,2,IF(0.53*I$7/$F16>=1,1,0)))) -> 1 | J16: =IF(J$7="",0,IF(INT(0.4*J$7/$F16)>=3,INT(0.4*J$7/$F16),IF(INT(0.31*J$7/$F16)>=2,2,IF(0.53*J$7/$F16>=1,1,0)))) -> 1 | K16: =IF(K$7="",0,IF(INT(0.4*K$7/$F16)>=3,INT(0.4*K$7/$F16),IF(INT(0.31*K$7/$F16)>=2,2,IF(0.53*K$7/$F16>=1,1,0)))) -> 3 | L16: =IF(L$7="",0,IF(INT(0.4*L$7/$F16)>=3,INT(0.4*L$7/$F16),IF(INT(0.31*L$7/$F16)>=2,2,IF(0.53*L$7/$F16>=1,1,0)))) -> 5 | M16: =IF(M$7="",0,IF(INT(0.4*M$7/$F16)>=3,INT(0.4*M$7/$F16),IF(INT(0.31*M$7/$F16)>=2,2,IF(0.53*M$7/$F16>=1,1,0)))) -> 7 | N16: =IF(N$7="",0,IF(INT(0.4*N$7/$F16)>=3,INT(0.4*N$7/$F16),IF(INT(0.31*N$7/$F16)>=2,2,IF(0.53*N$7/$F16>=1,1,0)))) -> 11 | ... P16: =IF(P$7="",0,IF(INT(0.4*P$7/$F16)>=3,INT(0.4*P$7/$F16),IF(INT(0.31*P$7/$F16)>=2,2,IF(0.53*P$7/$F16>=1,1,0)))) -> 20 | R16: =IFERROR($G16*$F16/G$7,"") -> 0 | S16: =IFERROR($H16*$F16/H$7,"") -> 0.4508335 | T16: =IFERROR($I16*$F16/I$7,"") -> 0.27798283 | U16: =IFERROR($J16*$F16/J$7,"") -> 0.16198087 | V16: =IFERROR($K16*$F16/K$7,"") -> 0.36118799 | W16: =IFERROR($L16*$F16/L$7,"") -> 0.37041767 | X16: =IFERROR($M16*$F16/M$7,"") -> 0.36778497 | Y16: =IFERROR($N16*$F16/N$7,"") -> 0.37565062 | Z16: =IFERROR($O16*$F16/O$7,"") -> 0.38408193 | AA16: =IFERROR($P16*$F16/P$7,"") -> 0.39839091
A17: AC | B17: Phelps Dodge CV/CV-FD-1C | 70 mm² | C17: 1 | D17: 70 | E17: 16 | F17: =PI()*E17^2/4 -> 201.06193 | G17: =IF(G$7="",0,IF(INT(0.4*G$7/$F17)>=3,INT(0.4*G$7/$F17),IF(INT(0.31*G$7/$F17)>=2,2,IF(0.53*G$7/$F17>=1,1,0)))) -> 0 | H17: =IF(H$7="",0,IF(INT(0.4*H$7/$F17)>=3,INT(0.4*H$7/$F17),IF(INT(0.31*H$7/$F17)>=2,2,IF(0.53*H$7/$F17>=1,1,0)))) -> 1 | I17: =IF(I$7="",0,IF(INT(0.4*I$7/$F17)>=3,INT(0.4*I$7/$F17),IF(INT(0.31*I$7/$F17)>=2,2,IF(0.53*I$7/$F17>=1,1,0)))) -> 1 | J17: =IF(J$7="",0,IF(INT(0.4*J$7/$F17)>=3,INT(0.4*J$7/$F17),IF(INT(0.31*J$7/$F17)>=2,2,IF(0.53*J$7/$F17>=1,1,0)))) -> 1 | K17: =IF(K$7="",0,IF(INT(0.4*K$7/$F17)>=3,INT(0.4*K$7/$F17),IF(INT(0.31*K$7/$F17)>=2,2,IF(0.53*K$7/$F17>=1,1,0)))) -> 2 | L17: =IF(L$7="",0,IF(INT(0.4*L$7/$F17)>=3,INT(0.4*L$7/$F17),IF(INT(0.31*L$7/$F17)>=2,2,IF(0.53*L$7/$F17>=1,1,0)))) -> 4 | M17: =IF(M$7="",0,IF(INT(0.4*M$7/$F17)>=3,INT(0.4*M$7/$F17),IF(INT(0.31*M$7/$F17)>=2,2,IF(0.53*M$7/$F17>=1,1,0)))) -> 6 | N17: =IF(N$7="",0,IF(INT(0.4*N$7/$F17)>=3,INT(0.4*N$7/$F17),IF(INT(0.31*N$7/$F17)>=2,2,IF(0.53*N$7/$F17>=1,1,0)))) -> 10 | ... P17: =IF(P$7="",0,IF(INT(0.4*P$7/$F17)>=3,INT(0.4*P$7/$F17),IF(INT(0.31*P$7/$F17)>=2,2,IF(0.53*P$7/$F17>=1,1,0)))) -> 17 | R17: =IFERROR($G17*$F17/G$7,"") -> 0 | S17: =IFERROR($H17*$F17/H$7,"") -> 0.51294834 | T17: =IFERROR($I17*$F17/I$7,"") -> 0.31628269 | U17: =IFERROR($J17*$F17/J$7,"") -> 0.18429824 | V17: =IFERROR($K17*$F17/K$7,"") -> 0.27396778 | W17: =IFERROR($L17*$F17/L$7,"") -> 0.3371624 | X17: =IFERROR($M17*$F17/M$7,"") -> 0.35867791 | Y17: =IFERROR($N17*$F17/N$7,"") -> 0.38855175 | Z17: =IFERROR($O17*$F17/O$7,"") -> 0.37873324 | AA17: =IFERROR($P17*$F17/P$7,"") -> 0.38528828
A18: AC | B18: Phelps Dodge CV/CV-FD-1C | 95 mm² | C18: 1 | D18: 95 | E18: 18 | F18: =PI()*E18^2/4 -> 254.469 | G18: =IF(G$7="",0,IF(INT(0.4*G$7/$F18)>=3,INT(0.4*G$7/$F18),IF(INT(0.31*G$7/$F18)>=2,2,IF(0.53*G$7/$F18>=1,1,0)))) -> 0 | H18: =IF(H$7="",0,IF(INT(0.4*H$7/$F18)>=3,INT(0.4*H$7/$F18),IF(INT(0.31*H$7/$F18)>=2,2,IF(0.53*H$7/$F18>=1,1,0)))) -> 0 | I18: =IF(I$7="",0,IF(INT(0.4*I$7/$F18)>=3,INT(0.4*I$7/$F18),IF(INT(0.31*I$7/$F18)>=2,2,IF(0.53*I$7/$F18>=1,1,0)))) -> 1 | J18: =IF(J$7="",0,IF(INT(0.4*J$7/$F18)>=3,INT(0.4*J$7/$F18),IF(INT(0.31*J$7/$F18)>=2,2,IF(0.53*J$7/$F18>=1,1,0)))) -> 1 | K18: =IF(K$7="",0,IF(INT(0.4*K$7/$F18)>=3,INT(0.4*K$7/$F18),IF(INT(0.31*K$7/$F18)>=2,2,IF(0.53*K$7/$F18>=1,1,0)))) -> 1 | L18: =IF(L$7="",0,IF(INT(0.4*L$7/$F18)>=3,INT(0.4*L$7/$F18),IF(INT(0.31*L$7/$F18)>=2,2,IF(0.53*L$7/$F18>=1,1,0)))) -> 3 | M18: =IF(M$7="",0,IF(INT(0.4*M$7/$F18)>=3,INT(0.4*M$7/$F18),IF(INT(0.31*M$7/$F18)>=2,2,IF(0.53*M$7/$F18>=1,1,0)))) -> 5 | N18: =IF(N$7="",0,IF(INT(0.4*N$7/$F18)>=3,INT(0.4*N$7/$F18),IF(INT(0.31*N$7/$F18)>=2,2,IF(0.53*N$7/$F18>=1,1,0)))) -> 8 | ... P18: =IF(P$7="",0,IF(INT(0.4*P$7/$F18)>=3,INT(0.4*P$7/$F18),IF(INT(0.31*P$7/$F18)>=2,2,IF(0.53*P$7/$F18>=1,1,0)))) -> 13 | R18: =IFERROR($G18*$F18/G$7,"") -> 0 | S18: =IFERROR($H18*$F18/H$7,"") -> 0 | T18: =IFERROR($I18*$F18/I$7,"") -> 0.40029528 | U18: =IFERROR($J18*$F18/J$7,"") -> 0.23325246 | V18: =IFERROR($K18*$F18/K$7,"") -> 0.17337024 | W18: =IFERROR($L18*$F18/L$7,"") -> 0.32004087 | X18: =IFERROR($M18*$F18/M$7,"") -> 0.37829311 | Y18: =IFERROR($N18*$F18/N$7,"") -> 0.39340865 | Z18: =IFERROR($O18*$F18/O$7,"") -> 0.36871866 | AA18: =IFERROR($P18*$F18/P$7,"") -> 0.37289389
A19: AC | B19: Phelps Dodge CV/CV-FD-1C | 120 mm² | C19: 1 | D19: 120 | E19: 20 | F19: =PI()*E19^2/4 -> 314.15927 | G19: =IF(G$7="",0,IF(INT(0.4*G$7/$F19)>=3,INT(0.4*G$7/$F19),IF(INT(0.31*G$7/$F19)>=2,2,IF(0.53*G$7/$F19>=1,1,0)))) -> 0 | H19: =IF(H$7="",0,IF(INT(0.4*H$7/$F19)>=3,INT(0.4*H$7/$F19),IF(INT(0.31*H$7/$F19)>=2,2,IF(0.53*H$7/$F19>=1,1,0)))) -> 0 | I19: =IF(I$7="",0,IF(INT(0.4*I$7/$F19)>=3,INT(0.4*I$7/$F19),IF(INT(0.31*I$7/$F19)>=2,2,IF(0.53*I$7/$F19>=1,1,0)))) -> 1 | J19: =IF(J$7="",0,IF(INT(0.4*J$7/$F19)>=3,INT(0.4*J$7/$F19),IF(INT(0.31*J$7/$F19)>=2,2,IF(0.53*J$7/$F19>=1,1,0)))) -> 1 | K19: =IF(K$7="",0,IF(INT(0.4*K$7/$F19)>=3,INT(0.4*K$7/$F19),IF(INT(0.31*K$7/$F19)>=2,2,IF(0.53*K$7/$F19>=1,1,0)))) -> 1 | L19: =IF(L$7="",0,IF(INT(0.4*L$7/$F19)>=3,INT(0.4*L$7/$F19),IF(INT(0.31*L$7/$F19)>=2,2,IF(0.53*L$7/$F19>=1,1,0)))) -> 3 | M19: =IF(M$7="",0,IF(INT(0.4*M$7/$F19)>=3,INT(0.4*M$7/$F19),IF(INT(0.31*M$7/$F19)>=2,2,IF(0.53*M$7/$F19>=1,1,0)))) -> 4 | N19: =IF(N$7="",0,IF(INT(0.4*N$7/$F19)>=3,INT(0.4*N$7/$F19),IF(INT(0.31*N$7/$F19)>=2,2,IF(0.53*N$7/$F19>=1,1,0)))) -> 6 | ... P19: =IF(P$7="",0,IF(INT(0.4*P$7/$F19)>=3,INT(0.4*P$7/$F19),IF(INT(0.31*P$7/$F19)>=2,2,IF(0.53*P$7/$F19>=1,1,0)))) -> 11 | R19: =IFERROR($G19*$F19/G$7,"") -> 0 | S19: =IFERROR($H19*$F19/H$7,"") -> 0 | T19: =IFERROR($I19*$F19/I$7,"") -> 0.4941917 | U19: =IFERROR($J19*$F19/J$7,"") -> 0.28796599 | V19: =IFERROR($K19*$F19/K$7,"") -> 0.21403733 | W19: =IFERROR($L19*$F19/L$7,"") -> 0.39511219 | X19: =IFERROR($M19*$F19/M$7,"") -> 0.37362283 | Y19: =IFERROR($N19*$F19/N$7,"") -> 0.36426727 | Z19: =IFERROR($O19*$F19/O$7,"") -> 0.36416657 | AA19: =IFERROR($P19*$F19/P$7,"") -> 0.38953778
A20: AC | B20: Phelps Dodge CV/CV-FD-1C | 150 mm² | C20: 1 | D20: 150 | E20: 22 | F20: =PI()*E20^2/4 -> 380.13271 | G20: =IF(INT(0.4*G$7/$F20)>=3,INT(0.4*G$7/$F20),IF(INT(0.31*G$7/$F20)>=2,2,IF(0.53*G$7/$F20>=1,1,0))) -> 0 | H20: =IF(INT(0.4*H$7/$F20)>=3,INT(0.4*H$7/$F20),IF(INT(0.31*H$7/$F20)>=2,2,IF(0.53*H$7/$F20>=1,1,0))) -> 0 | I20: =IF(INT(0.4*I$7/$F20)>=3,INT(0.4*I$7/$F20),IF(INT(0.31*I$7/$F20)>=2,2,IF(0.53*I$7/$F20>=1,1,0))) -> 0 | J20: =IF(INT(0.4*J$7/$F20)>=3,INT(0.4*J$7/$F20),IF(INT(0.31*J$7/$F20)>=2,2,IF(0.53*J$7/$F20>=1,1,0))) -> 1 | K20: =IF(INT(0.4*K$7/$F20)>=3,INT(0.4*K$7/$F20),IF(INT(0.31*K$7/$F20)>=2,2,IF(0.53*K$7/$F20>=1,1,0))) -> 1 | L20: =IF(INT(0.4*L$7/$F20)>=3,INT(0.4*L$7/$F20),IF(INT(0.31*L$7/$F20)>=2,2,IF(0.53*L$7/$F20>=1,1,0))) -> 1 | M20: =IF(INT(0.4*M$7/$F20)>=3,INT(0.4*M$7/$F20),IF(INT(0.31*M$7/$F20)>=2,2,IF(0.53*M$7/$F20>=1,1,0))) -> 3 | N20: =IF(INT(0.4*N$7/$F20)>=3,INT(0.4*N$7/$F20),IF(INT(0.31*N$7/$F20)>=2,2,IF(0.53*N$7/$F20>=1,1,0))) -> 5 | ... P20: =IF(INT(0.4*P$7/$F20)>=3,INT(0.4*P$7/$F20),IF(INT(0.31*P$7/$F20)>=2,2,IF(0.53*P$7/$F20>=1,1,0))) -> 9 | R20: =IFERROR($G20*$F20/G$7,"") -> 0 | S20: =IFERROR($H20*$F20/H$7,"") -> 0 | T20: =IFERROR($I20*$F20/I$7,"") -> 0 | U20: =IFERROR($J20*$F20/J$7,"") -> 0.34843885 | V20: =IFERROR($K20*$F20/K$7,"") -> 0.25898517 | W20: =IFERROR($L20*$F20/L$7,"") -> 0.15936191 | X20: =IFERROR($M20*$F20/M$7,"") -> 0.33906271 | Y20: =IFERROR($N20*$F20/N$7,"") -> 0.36730283 | Z20: =IFERROR($O20*$F20/O$7,"") -> 0.38556136 | AA20: =IFERROR($P20*$F20/P$7,"") -> 0.3856424
A21: AC | B21: Phelps Dodge CV/CV-FD-1C | 185 mm² | C21: 1 | D21: 185 | E21: 24 | F21: =PI()*E21^2/4 -> 452.38934 | G21: =IF(INT(0.4*G$7/$F21)>=3,INT(0.4*G$7/$F21),IF(INT(0.31*G$7/$F21)>=2,2,IF(0.53*G$7/$F21>=1,1,0))) -> 0 | H21: =IF(INT(0.4*H$7/$F21)>=3,INT(0.4*H$7/$F21),IF(INT(0.31*H$7/$F21)>=2,2,IF(0.53*H$7/$F21>=1,1,0))) -> 0 | I21: =IF(INT(0.4*I$7/$F21)>=3,INT(0.4*I$7/$F21),IF(INT(0.31*I$7/$F21)>=2,2,IF(0.53*I$7/$F21>=1,1,0))) -> 0 | J21: =IF(INT(0.4*J$7/$F21)>=3,INT(0.4*J$7/$F21),IF(INT(0.31*J$7/$F21)>=2,2,IF(0.53*J$7/$F21>=1,1,0))) -> 1 | K21: =IF(INT(0.4*K$7/$F21)>=3,INT(0.4*K$7/$F21),IF(INT(0.31*K$7/$F21)>=2,2,IF(0.53*K$7/$F21>=1,1,0))) -> 1 | L21: =IF(INT(0.4*L$7/$F21)>=3,INT(0.4*L$7/$F21),IF(INT(0.31*L$7/$F21)>=2,2,IF(0.53*L$7/$F21>=1,1,0))) -> 1 | M21: =IF(INT(0.4*M$7/$F21)>=3,INT(0.4*M$7/$F21),IF(INT(0.31*M$7/$F21)>=2,2,IF(0.53*M$7/$F21>=1,1,0))) -> 2 | N21: =IF(INT(0.4*N$7/$F21)>=3,INT(0.4*N$7/$F21),IF(INT(0.31*N$7/$F21)>=2,2,IF(0.53*N$7/$F21>=1,1,0))) -> 4 | ... P21: =IF(INT(0.4*P$7/$F21)>=3,INT(0.4*P$7/$F21),IF(INT(0.31*P$7/$F21)>=2,2,IF(0.53*P$7/$F21>=1,1,0))) -> 7 | R21: =IFERROR($G21*$F21/G$7,"") -> 0 | S21: =IFERROR($H21*$F21/H$7,"") -> 0 | T21: =IFERROR($I21*$F21/I$7,"") -> 0 | U21: =IFERROR($J21*$F21/J$7,"") -> 0.41467103 | V21: =IFERROR($K21*$F21/K$7,"") -> 0.30821375 | W21: =IFERROR($L21*$F21/L$7,"") -> 0.18965385 | X21: =IFERROR($M21*$F21/M$7,"") -> 0.26900843 | Y21: =IFERROR($N21*$F21/N$7,"") -> 0.34969658 | Z21: =IFERROR($O21*$F21/O$7,"") -> 0.3932999 | AA21: =IFERROR($P21*$F21/P$7,"") -> 0.35695826
A22: AC | B22: Phelps Dodge CV/CV-FD-1C | 240 mm² | C22: 1 | D22: 240 | E22: 27 | F22: =PI()*E22^2/4 -> 572.55526 | G22: =IF(INT(0.4*G$7/$F22)>=3,INT(0.4*G$7/$F22),IF(INT(0.31*G$7/$F22)>=2,2,IF(0.53*G$7/$F22>=1,1,0))) -> 0 | H22: =IF(INT(0.4*H$7/$F22)>=3,INT(0.4*H$7/$F22),IF(INT(0.31*H$7/$F22)>=2,2,IF(0.53*H$7/$F22>=1,1,0))) -> 0 | I22: =IF(INT(0.4*I$7/$F22)>=3,INT(0.4*I$7/$F22),IF(INT(0.31*I$7/$F22)>=2,2,IF(0.53*I$7/$F22>=1,1,0))) -> 0 | J22: =IF(INT(0.4*J$7/$F22)>=3,INT(0.4*J$7/$F22),IF(INT(0.31*J$7/$F22)>=2,2,IF(0.53*J$7/$F22>=1,1,0))) -> 1 | K22: =IF(INT(0.4*K$7/$F22)>=3,INT(0.4*K$7/$F22),IF(INT(0.31*K$7/$F22)>=2,2,IF(0.53*K$7/$F22>=1,1,0))) -> 1 | L22: =IF(INT(0.4*L$7/$F22)>=3,INT(0.4*L$7/$F22),IF(INT(0.31*L$7/$F22)>=2,2,IF(0.53*L$7/$F22>=1,1,0))) -> 1 | M22: =IF(INT(0.4*M$7/$F22)>=3,INT(0.4*M$7/$F22),IF(INT(0.31*M$7/$F22)>=2,2,IF(0.53*M$7/$F22>=1,1,0))) -> 1 | N22: =IF(INT(0.4*N$7/$F22)>=3,INT(0.4*N$7/$F22),IF(INT(0.31*N$7/$F22)>=2,2,IF(0.53*N$7/$F22>=1,1,0))) -> 3 | ... P22: =IF(INT(0.4*P$7/$F22)>=3,INT(0.4*P$7/$F22),IF(INT(0.31*P$7/$F22)>=2,2,IF(0.53*P$7/$F22>=1,1,0))) -> 6 | R22: =IFERROR($G22*$F22/G$7,"") -> 0 | S22: =IFERROR($H22*$F22/H$7,"") -> 0 | T22: =IFERROR($I22*$F22/I$7,"") -> 0 | U22: =IFERROR($J22*$F22/J$7,"") -> 0.52481803 | V22: =IFERROR($K22*$F22/K$7,"") -> 0.39008303 | W22: =IFERROR($L22*$F22/L$7,"") -> 0.24003065 | X22: =IFERROR($M22*$F22/M$7,"") -> 0.1702319 | Y22: =IFERROR($N22*$F22/N$7,"") -> 0.33193855 | Z22: =IFERROR($O22*$F22/O$7,"") -> 0.33184679 | AA22: =IFERROR($P22*$F22/P$7,"") -> 0.38723597
A23: AC | B23: Phelps Dodge CV/CV-FD-1C | 300 mm² | C23: 1 | D23: 300 | E23: 30 | F23: =PI()*E23^2/4 -> 706.85835 | G23: =IF(INT(0.4*G$7/$F23)>=3,INT(0.4*G$7/$F23),IF(INT(0.31*G$7/$F23)>=2,2,IF(0.53*G$7/$F23>=1,1,0))) -> 0 | H23: =IF(INT(0.4*H$7/$F23)>=3,INT(0.4*H$7/$F23),IF(INT(0.31*H$7/$F23)>=2,2,IF(0.53*H$7/$F23>=1,1,0))) -> 0 | I23: =IF(INT(0.4*I$7/$F23)>=3,INT(0.4*I$7/$F23),IF(INT(0.31*I$7/$F23)>=2,2,IF(0.53*I$7/$F23>=1,1,0))) -> 0 | J23: =IF(INT(0.4*J$7/$F23)>=3,INT(0.4*J$7/$F23),IF(INT(0.31*J$7/$F23)>=2,2,IF(0.53*J$7/$F23>=1,1,0))) -> 0 | K23: =IF(INT(0.4*K$7/$F23)>=3,INT(0.4*K$7/$F23),IF(INT(0.31*K$7/$F23)>=2,2,IF(0.53*K$7/$F23>=1,1,0))) -> 1 | L23: =IF(INT(0.4*L$7/$F23)>=3,INT(0.4*L$7/$F23),IF(INT(0.31*L$7/$F23)>=2,2,IF(0.53*L$7/$F23>=1,1,0))) -> 1 | M23: =IF(INT(0.4*M$7/$F23)>=3,INT(0.4*M$7/$F23),IF(INT(0.31*M$7/$F23)>=2,2,IF(0.53*M$7/$F23>=1,1,0))) -> 1 | N23: =IF(INT(0.4*N$7/$F23)>=3,INT(0.4*N$7/$F23),IF(INT(0.31*N$7/$F23)>=2,2,IF(0.53*N$7/$F23>=1,1,0))) -> 2 | ... P23: =IF(INT(0.4*P$7/$F23)>=3,INT(0.4*P$7/$F23),IF(INT(0.31*P$7/$F23)>=2,2,IF(0.53*P$7/$F23>=1,1,0))) -> 5 | R23: =IFERROR($G23*$F23/G$7,"") -> 0 | S23: =IFERROR($H23*$F23/H$7,"") -> 0 | T23: =IFERROR($I23*$F23/I$7,"") -> 0 | U23: =IFERROR($J23*$F23/J$7,"") -> 0 | V23: =IFERROR($K23*$F23/K$7,"") -> 0.48158399 | W23: =IFERROR($L23*$F23/L$7,"") -> 0.29633414 | X23: =IFERROR($M23*$F23/M$7,"") -> 0.21016284 | Y23: =IFERROR($N23*$F23/N$7,"") -> 0.27320045 | Z23: =IFERROR($O23*$F23/O$7,"") -> 0.30726555 | AA23: =IFERROR($P23*$F23/P$7,"") -> 0.39839091
